Workbook

Sheet All
N1: 44592
A2: ល.រ | B2: Factory ID | C2: គោត្តនាម | D2: នាម | E2: គោត្តនាមឡាតាំង | F2: នាមឡាតាំង | G2: ភេទ | H2: ថ្ងៃខែឆ្នាំកំណើត | I2: កាលបរិ. ចូលធ្វើការ | J2: ផ្នែក | K2: ក្រុម | L2: តួនាទី | M2: Salary Report 2021 | U2: Adjust amount | V2: Adjust Date | W2: Evaluator | X2: 2022 Total Marks | Y2: With Comment | Z2: Salary Report 2022
A3: Nº | B3: Factory ID | C3: Khmer Sure name | D3: Khmer Name | E3: English Sure name | F3: Khmer Name | G3: Sex | H3: Birth of Date | I3: Join Date | J3: Department | K3: Group | L3: Position | M3: Basic | N3: Seniority | O3: Skill | P3: Position | Q3: Language | R3: Housing &Transportation | S3: Motivation | T3: Total | U3: 調動金額 | V3: 調動日期 | W3: 評核人 | X3: 2021總分 | Y3: 意見 | Z3: Basic | AA3: Seniority | AB3: Skill | AC3: Position | AD3: Language | AE3: Housing &Transportation | AF3: Motivation | AG3: Total
A4: =1 -> 1 | B4: 2168 | C4: យិន | D4: ផារី | E4: YIN | F4: PHARY | G4: F | H4: 32278 | I4: 43192 | J4: ADMINISTRATION | K4: HR | L4: Leader | T4: =SUM(M4:S4) -> 0 | Z4: =M4+2 -> 2 | AA4: =N4 -> 0 | AB4: =O4 -> 0 | AC4: =P4 -> 0 | AD4: =Q4 -> 0 | AE4: =R4 -> 0 | AF4: =S4 -> 0 | AG4: =SUM(Z4:AF4) -> 2 | AH4: =Z4-M4 -> 2 | AI4: =AA4-N4 -> 0 | AJ4: =AB4-O4 -> 0 | AK4: =AC4-P4 -> 0 | AL4: =AD4-Q4 -> 0 | AM4: =AE4-R4 -> 0 | AN4: =AF4-S4 -> 0 | AO4: =AG4-T4 -> 2
A5: =1+A4 -> 2 | B5: 2360 | C5: ម៉ម | D5: រត្ននី | E5: MAM | F5: ROTNY | G5: F | H5: 31391 | I5: 43252 | J5: ADMINISTRATION | K5: Admin | L5: Ass. Admin | T5: =SUM(M5:S5) -> 0 | Z5: =M5+2 -> 2 | AA5: =N5 -> 0 | AB5: =O5 -> 0 | AC5: =P5 -> 0 | AD5: =Q5 -> 0 | AE5: =R5 -> 0 | AF5: =S5 -> 0 | AG5: =SUM(Z5:AF5) -> 2 | AH5: =Z5-M5 -> 2 | AI5: =AA5-N5 -> 0 | AJ5: =AB5-O5 -> 0 | AK5: =AC5-P5 -> 0 | AL5: =AD5-Q5 -> 0 | AM5: =AE5-R5 -> 0 | AN5: =AF5-S5 -> 0 | AO5: =AG5-T5 -> 2
A6: =1+A5 -> 3 | B6: 4 | C6: ពុធ | D6: ធារី | E6: Put | F6: Theary | G6: F | H6: 30411 | I6: 41575 | J6: Shipping | K6: Import | L6: Leader | M6: 200 | N6: 9 | O6: 66 | P6: 250 | Q6: 175 | R6: 7 | S6: 10 | T6: =SUM(M6:S6) -> 717 | Z6: =M6+2 -> 202 | AA6: =N6 -> 9 | AB6: =O6 -> 66 | AC6: =P6 -> 250 | AD6: =Q6 -> 175 | AE6: =R6 -> 7 | AF6: =S6 -> 10 | AG6: =SUM(Z6:AF6) -> 719 | AH6: =Z6-M6 -> 2 | AI6: =AA6-N6 -> 0 | AJ6: =AB6-O6 -> 0 | AK6: =AC6-P6 -> 0 | AL6: =AD6-Q6 -> 0 | AM6: =AE6-R6 -> 0 | AN6: =AF6-S6 -> 0 | AO6: =AG6-T6 -> 2
A7: =1+A6 -> 4 | B7: 2 | C7: អ៊ូច | D7: ចាន់ម៉ាឡែន | E7: Ouch | F7: Chanmalen | G7: M | H7: 32387 | I7: 41575 | J7: IT | K7: IT | L7: Leader | T7: =SUM(M7:S7) -> 0 | Z7: =M7+2 -> 2 | AA7: =N7 -> 0 | AB7: =O7 -> 0 | AC7: =P7 -> 0 | AD7: =Q7 -> 0 | AE7: =R7 -> 0 | AF7: =S7 -> 0 | AG7: =SUM(Z7:AF7) -> 2 | AH7: =Z7-M7 -> 2 | AI7: =AA7-N7 -> 0 | AJ7: =AB7-O7 -> 0 | AK7: =AC7-P7 -> 0 | AL7: =AD7-Q7 -> 0 | AM7: =AE7-R7 -> 0 | AN7: =AF7-S7 -> 0 | AO7: =AG7-T7 -> 2
A8: =1+A7 -> 5 | B8: 10 | C8: ញ៉ិល | D8: ចន័្នធា | E8: NHEL | F8: CHANTHEA | G8: F | H8: 30135 | I8: 41575 | J8: Production | K8: Supervisor | L8: supervisor Line 17,18,19,20,21 | M8: 192 | N8: =ROUNDDOWN(INT($N$1-I8-16)/365,0)+1 -> 9 | O8: 20 | P8: 195 | Q8: 75 | R8: 7 | S8: 10 | T8: =SUM(M8:S8) -> 508 | Z8: =M8+2 -> 194 | AA8: =N8 -> 9 | AB8: =O8 -> 20 | AC8: =P8 -> 195 | AD8: =Q8 -> 75 | AE8: =R8 -> 7 | AF8: =S8 -> 10 | AG8: =SUM(Z8:AF8) -> 510 | AH8: =Z8-M8 -> 2 | AI8: =AA8-N8 -> 0 | AJ8: =AB8-O8 -> 0 | AK8: =AC8-P8 -> 0 | AL8: =AD8-Q8 -> 0 | AM8: =AE8-R8 -> 0 | AN8: =AF8-S8 -> 0 | AO8: =AG8-T8 -> 2 | AR8: 4
A9: =1+A8 -> 6 | B9: 14 | C9: គឹម | D9: សារិន | E9: Koem | F9: Sarim | G9: F | H9: 27490 | I9: 41573 | J9: ADMINISTRATION | K9: GA | L9: Cleaner | M9: 192 | N9: =ROUNDDOWN(INT($N$1-I9-16)/365,0)+1 -> 9 | O9: 20 | P9: 50 | Q9: 0 | R9: 7 | S9: 10 | T9: =SUM(M9:S9) -> 288 | Z9: =M9+2 -> 194 | AA9: =N9 -> 9 | AB9: =O9 -> 20 | AC9: =P9 -> 50 | AD9: =Q9 -> 0 | AE9: =R9 -> 7 | AF9: =S9 -> 10 | AG9: =SUM(Z9:AF9) -> 290 | AH9: =Z9-M9 -> 2 | AI9: =AA9-N9 -> 0 | AJ9: =AB9-O9 -> 0 | AK9: =AC9-P9 -> 0 | AL9: =AD9-Q9 -> 0 | AM9: =AE9-R9 -> 0 | AN9: =AF9-S9 -> 0 | AO9: =AG9-T9 -> 2 | AR9: 2
A10: =1+A9 -> 7 | B10: 18 | C10: ស្រី | D10: ច័ន្ទថុនា | E10: Srey | F10: Chanthuna | G10: M | H10: 33771 | I10: 41577 | J10: Production Development | K10: Development | L10: Marker technicial | M10: 262 | N10: =ROUNDDOWN(INT($N$1-I10-16)/365,0)+1 -> 9 | O10: 20 | P10: 72 | Q10: 66 | R10: 7 | S10: 10 | T10: =SUM(M10:S10) -> 446 | Z10: =M10+2 -> 264 | AA10: =N10 -> 9 | AB10: =O10 -> 20 | AC10: =P10 -> 72 | AD10: =Q10 -> 66 | AE10: =R10 -> 7 | AF10: =S10 -> 10 | AG10: =SUM(Z10:AF10) -> 448 | AH10: =Z10-M10 -> 2 | AI10: =AA10-N10 -> 0 | AJ10: =AB10-O10 -> 0 | AK10: =AC10-P10 -> 0 | AL10: =AD10-Q10 -> 0 | AM10: =AE10-R10 -> 0 | AN10: =AF10-S10 -> 0 | AO10: =AG10-T10 -> 2 | AR10: 1012
A11: =1+A10 -> 8 | B11: 24 | C11: អ៊ឹម | D11: ផានី | E11: Im | F11: Phany | G11: F | H11: 30165 | I11: 41579 | J11: Production | K11: Line3 | L11: Leader Line 3 | M11: 192 | N11: =ROUNDDOWN(INT($N$1-I11-16)/365,0)+1 -> 9 | O11: 20 | P11: 52 | Q11: 15 | R11: 7 | S11: 10 | T11: =SUM(M11:S11) -> 305 | Z11: =M11+2 -> 194 | AA11: =N11 -> 9 | AB11: =O11 -> 20 | AC11: =P11 -> 52 | AD11: =Q11 -> 15 | AE11: =R11 -> 7 | AF11: =S11 -> 10 | AG11: =SUM(Z11:AF11) -> 307 | AH11: =Z11-M11 -> 2 | AI11: =AA11-N11 -> 0 | AJ11: =AB11-O11 -> 0 | AK11: =AC11-P11 -> 0 | AL11: =AD11-Q11 -> 0 | AM11: =AE11-R11 -> 0 | AN11: =AF11-S11 -> 0 | AO11: =AG11-T11 -> 2
A12: =1+A11 -> 9 | B12: 30 | C12: ភោក | D12: ស៊ីណា | E12: Phouk | F12: Sina | G12: F | H12: 29927 | I12: 41579 | J12: Production | K12: Supervisor | L12: supervisor Line 1,2,3,15 | M12: 192 | N12: =ROUNDDOWN(INT($N$1-I12-16)/365,0)+1 -> 9 | O12: 20 | P12: 175 | Q12: 75 | R12: 7 | S12: 10 | T12: =SUM(M12:S12) -> 488 | Z12: =M12+2 -> 194 | AA12: =N12 -> 9 | AB12: =O12 -> 20 | AC12: =P12 -> 175 | AD12: =Q12 -> 75 | AE12: =R12 -> 7 | AF12: =S12 -> 10 | AG12: =SUM(Z12:AF12) -> 490 | AH12: =Z12-M12 -> 2 | AI12: =AA12-N12 -> 0 | AJ12: =AB12-O12 -> 0 | AK12: =AC12-P12 -> 0 | AL12: =AD12-Q12 -> 0 | AM12: =AE12-R12 -> 0 | AN12: =AF12-S12 -> 0 | AO12: =AG12-T12 -> 2
A13: =1+A12 -> 10 | B13: 32 | C13: ហៀ | D13: ហឿង | E13: Hear | F13: Hoeung | G13: F | H13: 27885 | I13: 41579 | J13: Production | K13: Supervisor | L13: supervisor L 8,9,10,11 | M13: 192 | N13: =ROUNDDOWN(INT($N$1-I13-16)/365,0)+1 -> 9 | O13: 0 | P13: 260 | Q13: 50 | R13: 7 | S13: 10 | T13: =SUM(M13:S13) -> 528 | Z13: =M13+2 -> 194 | AA13: =N13 -> 9 | AB13: =O13 -> 0 | AC13: =P13 -> 260 | AD13: =Q13 -> 50 | AE13: =R13 -> 7 | AF13: =S13 -> 10 | AG13: =SUM(Z13:AF13) -> 530 | AH13: =Z13-M13 -> 2 | AI13: =AA13-N13 -> 0 | AJ13: =AB13-O13 -> 0 | AK13: =AC13-P13 -> 0 | AL13: =AD13-Q13 -> 0 | AM13: =AE13-R13 -> 0 | AN13: =AF13-S13 -> 0 | AO13: =AG13-T13 -> 2
A14: =1+A13 -> 11 | B14: 39 | C14: អ៊ឹម | D14: ស្រីល័ក្ខ | E14: Oem | F14: Srey Leak | G14: F | H14: 32600 | I14: 41579 | J14: Production | K14: QC | L14: supervisor Line | T14: =SUM(M14:S14) -> 0 | Z14: =M14+2 -> 2 | AA14: =N14 -> 0 | AB14: =O14 -> 0 | AC14: =P14 -> 0 | AD14: =Q14 -> 0 | AE14: =R14 -> 0 | AF14: =S14 -> 0 | AG14: =SUM(Z14:AF14) -> 2 | AH14: =Z14-M14 -> 2 | AI14: =AA14-N14 -> 0 | AJ14: =AB14-O14 -> 0 | AK14: =AC14-P14 -> 0 | AL14: =AD14-Q14 -> 0 | AM14: =AE14-R14 -> 0 | AN14: =AF14-S14 -> 0 | AO14: =AG14-T14 -> 2
A15: =1+A14 -> 12 | B15: 44 | C15: ប៊ុន | D15: គឹមសែ | E15: Bun | F15: Kimse | G15: F | H15: 31836 | I15: 41579 | J15: Production | K15: Line19 | L15: Assist.Line 19 | M15: 192 | N15: =ROUNDDOWN(INT($N$1-I15-16)/365,0)+1 -> 9 | O15: 20 | P15: 30 | Q15: 10 | R15: 7 | S15: 10 | T15: =SUM(M15:S15) -> 278 | Z15: =M15+2 -> 194 | AA15: =N15 -> 9 | AB15: =O15 -> 20 | AC15: =P15 -> 30 | AD15: =Q15 -> 10 | AE15: =R15 -> 7 | AF15: =S15 -> 10 | AG15: =SUM(Z15:AF15) -> 280 | AH15: =Z15-M15 -> 2 | AI15: =AA15-N15 -> 0 | AJ15: =AB15-O15 -> 0 | AK15: =AC15-P15 -> 0 | AL15: =AD15-Q15 -> 0 | AM15: =AE15-R15 -> 0 | AN15: =AF15-S15 -> 0 | AO15: =AG15-T15 -> 2
A16: =1+A15 -> 13 | B16: 47 | C16: ឃុន | D16: សាខន | E16: Khun | F16: Sakhân | G16: F | H16: 24152 | I16: 41583 | J16: Production | K16: Line8 | L16: Sewing operator | M16: 199 | N16: =ROUNDDOWN(INT($N$1-I16-16)/365,0)+1 -> 9 | O16: 20 | P16: 0 | Q16: 0 | R16: 7 | S16: 10 | T16: =SUM(M16:S16) -> 245 | Z16: =M16+2 -> 201 | AA16: =N16 -> 9 | AB16: =O16 -> 20 | AC16: =P16 -> 0 | AD16: =Q16 -> 0 | AE16: =R16 -> 7 | AF16: =S16 -> 10 | AG16: =SUM(Z16:AF16) -> 247 | AH16: =Z16-M16 -> 2 | AI16: =AA16-N16 -> 0 | AJ16: =AB16-O16 -> 0 | AK16: =AC16-P16 -> 0 | AL16: =AD16-Q16 -> 0 | AM16: =AE16-R16 -> 0 | AN16: =AF16-S16 -> 0 | AO16: =AG16-T16 -> 2
A17: =1+A16 -> 14 | B17: 67 | C17: ហុង | D17: សេងចន្នី | E17: HONG | F17: SENG CHANNY | G17: F | H17: 30439 | I17: 41591 | J17: Production | K17: Line9 | L17: Sewing operator | M17: 192 | N17: =ROUNDDOWN(INT($N$1-I17-16)/365,0)+1 -> 9 | O17: 20 | P17: 0 | Q17: 0 | R17: 7 | S17: 10 | T17: =SUM(M17:S17) -> 238 | Z17: =M17+2 -> 194 | AA17: =N17 -> 9 | AB17: =O17 -> 20 | AC17: =P17 -> 0 | AD17: =Q17 -> 0 | AE17: =R17 -> 7 | AF17: =S17 -> 10 | AG17: =SUM(Z17:AF17) -> 240 | AH17: =Z17-M17 -> 2 | AI17: =AA17-N17 -> 0 | AJ17: =AB17-O17 -> 0 | AK17: =AC17-P17 -> 0 | AL17: =AD17-Q17 -> 0 | AM17: =AE17-R17 -> 0 | AN17: =AF17-S17 -> 0 | AO17: =AG17-T17 -> 2
A18: =1+A17 -> 15 | B18: 69 | C18: ធង | D18: អួន | E18: THORNG | F18: UON | G18: F | H18: 29285 | I18: 41591 | J18: Production | K18: Line21 | L18: Sewing operator | M18: 192 | N18: =ROUNDDOWN(INT($N$1-I18-16)/365,0)+1 -> 9 | O18: 20 | P18: 0 | Q18: 0 | R18: 7 | S18: 10 | T18: =SUM(M18:S18) -> 238 | Z18: =M18+2 -> 194 | AA18: =N18 -> 9 | AB18: =O18 -> 20 | AC18: =P18 -> 0 | AD18: =Q18 -> 0 | AE18: =R18 -> 7 | AF18: =S18 -> 10 | AG18: =SUM(Z18:AF18) -> 240 | AH18: =Z18-M18 -> 2 | AI18: =AA18-N18 -> 0 | AJ18: =AB18-O18 -> 0 | AK18: =AC18-P18 -> 0 | AL18: =AD18-Q18 -> 0 | AM18: =AE18-R18 -> 0 | AN18: =AF18-S18 -> 0 | AO18: =AG18-T18 -> 2
A19: =1+A18 -> 16 | B19: 74 | C19: ពេជ | D19: សោភា | E19: Pich | F19: Sophea | G19: F | H19: 29108 | I19: 41598 | J19: Production | K19: Line17 | L19: Leader Line 17 | M19: 192 | N19: =ROUNDDOWN(INT($N$1-I19-16)/365,0)+1 -> 9 | O19: 20 | P19: 47 | Q19: 15 | R19: 7 | S19: 10 | T19: =SUM(M19:S19) -> 300 | Z19: =M19+2 -> 194 | AA19: =N19 -> 9 | AB19: =O19 -> 20 | AC19: =P19 -> 47 | AD19: =Q19 -> 15 | AE19: =R19 -> 7 | AF19: =S19 -> 10 | AG19: =SUM(Z19:AF19) -> 302 | AH19: =Z19-M19 -> 2 | AI19: =AA19-N19 -> 0 | AJ19: =AB19-O19 -> 0 | AK19: =AC19-P19 -> 0 | AL19: =AD19-Q19 -> 0 | AM19: =AE19-R19 -> 0 | AN19: =AF19-S19 -> 0 | AO19: =AG19-T19 -> 2
A20: =1+A19 -> 17 | B20: 78 | C20: ម៉ូវ | D20: សុធឿន | E20: MOUV | F20: SOTHOEUNRN | G20: F | H20: 31630 | I20: 41598 | J20: Production | K20: Line10 | L20: Sewing operator | M20: 192 | N20: =ROUNDDOWN(INT($N$1-I20-16)/365,0)+1 -> 9 | O20: 20 | P20: 0 | Q20: 0 | R20: 7 | S20: 10 | T20: =SUM(M20:S20) -> 238 | Z20: =M20+2 -> 194 | AA20: =N20 -> 9 | AB20: =O20 -> 20 | AC20: =P20 -> 0 | AD20: =Q20 -> 0 | AE20: =R20 -> 7 | AF20: =S20 -> 10 | AG20: =SUM(Z20:AF20) -> 240 | AH20: =Z20-M20 -> 2 | AI20: =AA20-N20 -> 0 | AJ20: =AB20-O20 -> 0 | AK20: =AC20-P20 -> 0 | AL20: =AD20-Q20 -> 0 | AM20: =AE20-R20 -> 0 | AN20: =AF20-S20 -> 0 | AO20: =AG20-T20 -> 2
A21: =1+A20 -> 18 | B21: 81 | C21: វ៉ន | D21: ភា | E21: Vorn | F21: Phea | G21: F | H21: 28299 | I21: 41599 | J21: Production | K21: Line10 | L21: Sewing operator | M21: 192 | N21: =ROUNDDOWN(INT($N$1-I21-16)/365,0)+1 -> 9 | O21: 20 | P21: 0 | Q21: 0 | R21: 7 | S21: 10 | T21: =SUM(M21:S21) -> 238 | Z21: =M21+2 -> 194 | AA21: =N21 -> 9 | AB21: =O21 -> 20 | AC21: =P21 -> 0 | AD21: =Q21 -> 0 | AE21: =R21 -> 7 | AF21: =S21 -> 10 | AG21: =SUM(Z21:AF21) -> 240 | AH21: =Z21-M21 -> 2 | AI21: =AA21-N21 -> 0 | AJ21: =AB21-O21 -> 0 | AK21: =AC21-P21 -> 0 | AL21: =AD21-Q21 -> 0 | AM21: =AE21-R21 -> 0 | AN21: =AF21-S21 -> 0 | AO21: =AG21-T21 -> 2
A22: =1+A21 -> 19 | B22: 90 | C22: ហឿង | D22: សុខឡាង | E22: HOEUNG | F22: SOK LANG | G22: F | H22: 33244 | I22: 41598 | J22: Production | K22: Line10 | L22: Sewing operator | M22: 192 | N22: =ROUNDDOWN(INT($N$1-I22-16)/365,0)+1 -> 9 | O22: 20 | P22: 0 | Q22: 0 | R22: 7 | S22: 10 | T22: =SUM(M22:S22) -> 238 | Z22: =M22+2 -> 194 | AA22: =N22 -> 9 | AB22: =O22 -> 20 | AC22: =P22 -> 0 | AD22: =Q22 -> 0 | AE22: =R22 -> 7 | AF22: =S22 -> 10 | AG22: =SUM(Z22:AF22) -> 240 | AH22: =Z22-M22 -> 2 | AI22: =AA22-N22 -> 0 | AJ22: =AB22-O22 -> 0 | AK22: =AC22-P22 -> 0 | AL22: =AD22-Q22 -> 0 | AM22: =AE22-R22 -> 0 | AN22: =AF22-S22 -> 0 | AO22: =AG22-T22 -> 2
A23: =1+A22 -> 20 | B23: 113 | C23: អៀម | D23: សារីម | E23: IEM | F23: SARIM | G23: F | H23: 29385 | I23: 41612 | J23: Production | K23: Line1 | L23: Sewing operator | M23: 192 | N23: =ROUNDDOWN(INT($N$1-I23-16)/365,0)+1 -> 9 | O23: 20 | P23: 0 | Q23: 0 | R23: 7 | S23: 10 | T23: =SUM(M23:S23) -> 238 | Z23: =M23+2 -> 194 | AA23: =N23 -> 9 | AB23: =O23 -> 20 | AC23: =P23 -> 0 | AD23: =Q23 -> 0 | AE23: =R23 -> 7 | AF23: =S23 -> 10 | AG23: =SUM(Z23:AF23) -> 240 | AH23: =Z23-M23 -> 2 | AI23: =AA23-N23 -> 0 | AJ23: =AB23-O23 -> 0 | AK23: =AC23-P23 -> 0 | AL23: =AD23-Q23 -> 0 | AM23: =AE23-R23 -> 0 | AN23: =AF23-S23 -> 0 | AO23: =AG23-T23 -> 2 | AT23: =VLOOKUP(#REF!,All!$B$4:$S$8977,4,FALSE) -> #REF! | AU23: =VLOOKUP(#REF!,All!$B$4:$S$8977,5,FALSE) -> #REF!
A24: =1+A23 -> 21 | B24: 146 | C24: ទៀប | D24: សូនី | E24: Teab | F24: sony | G24: F | H24: 25950 | I24: 41619 | J24: Production | K24: Line2 | L24: Sewing operator | M24: 192 | N24: =ROUNDDOWN(INT($N$1-I24-16)/365,0)+1 -> 9 | O24: 20 | P24: 0 | Q24: 0 | R24: 7 | S24: 10 | T24: =SUM(M24:S24) -> 238 | Z24: =M24+2 -> 194 | AA24: =N24 -> 9 | AB24: =O24 -> 20 | AC24: =P24 -> 0 | AD24: =Q24 -> 0 | AE24: =R24 -> 7 | AF24: =S24 -> 10 | AG24: =SUM(Z24:AF24) -> 240 | AH24: =Z24-M24 -> 2 | AI24: =AA24-N24 -> 0 | AJ24: =AB24-O24 -> 0 | AK24: =AC24-P24 -> 0 | AL24: =AD24-Q24 -> 0 | AM24: =AE24-R24 -> 0 | AN24: =AF24-S24 -> 0 | AO24: =AG24-T24 -> 2 | AT24: =VLOOKUP(#REF!,All!$B$4:$S$8977,4,FALSE) -> #REF! | AU24: =VLOOKUP(#REF!,All!$B$4:$S$8977,5,FALSE) -> #REF!
A25: =1+A24 -> 22 | B25: 161 | C25: សែត | D25: មឿន | E25: Set | F25: moeun | G25: F | H25: 34710 | I25: 41674 | J25: Production | K25: Line1 | L25: Leader Line 1 | M25: 192 | N25: =ROUNDDOWN(INT($N$1-I25-16)/365,0)+1 -> 8 | O25: 20 | P25: 45 | Q25: 0 | R25: 7 | S25: 10 | T25: =SUM(M25:S25) -> 282 | Z25: =M25+2 -> 194 | AA25: =N25 -> 8 | AB25: =O25 -> 20 | AC25: =P25 -> 45 | AD25: =Q25 -> 0 | AE25: =R25 -> 7 | AF25: =S25 -> 10 | AG25: =SUM(Z25:AF25) -> 284 | AH25: =Z25-M25 -> 2 | AI25: =AA25-N25 -> 0 | AJ25: =AB25-O25 -> 0 | AK25: =AC25-P25 -> 0 | AL25: =AD25-Q25 -> 0 | AM25: =AE25-R25 -> 0 | AN25: =AF25-S25 -> 0 | AO25: =AG25-T25 -> 2 | AT25: =VLOOKUP(#REF!,All!$B$4:$S$8977,4,FALSE) -> #REF! | AU25: =VLOOKUP(#REF!,All!$B$4:$S$8977,5,FALSE) -> #REF!
A26: =1+A25 -> 23 | B26: 163 | C26: ខៀវ | D26: ចាន់នួន | E26: keav | F26: channoun | G26: F | H26: 30297 | I26: 41676 | J26: Production | K26: Sample | L26: Leader Sample | M26: 192 | N26: =ROUNDDOWN(INT($N$1-I26-16)/365,0)+1 -> 8 | O26: 20 | P26: 45 | Q26: 0 | R26: 7 | S26: 10 | T26: =SUM(M26:S26) -> 282 | Z26: =M26+2 -> 194 | AA26: =N26 -> 8 | AB26: =O26 -> 20 | AC26: =P26 -> 45 | AD26: =Q26 -> 0 | AE26: =R26 -> 7 | AF26: =S26 -> 10 | AG26: =SUM(Z26:AF26) -> 284 | AH26: =Z26-M26 -> 2 | AI26: =AA26-N26 -> 0 | AJ26: =AB26-O26 -> 0 | AK26: =AC26-P26 -> 0 | AL26: =AD26-Q26 -> 0 | AM26: =AE26-R26 -> 0 | AN26: =AF26-S26 -> 0 | AO26: =AG26-T26 -> 2 | AT26: =VLOOKUP(#REF!,All!$B$4:$S$8977,4,FALSE) -> #REF! | AU26: =VLOOKUP(#REF!,All!$B$4:$S$8977,5,FALSE) -> #REF!
A27: =1+A26 -> 24 | B27: 171 | C27: សោម | D27: ចន្ធី | E27: Som | F27: Chanthy | G27: F | H27: 32617 | I27: 41680 | J27: ADMINISTRATION | K27: HR | L27: Nurse | M27: 192 | N27: =ROUNDDOWN(INT($N$1-I27-16)/365,0)+1 -> 8 | O27: 0 | P27: 118 | Q27: 35 | R27: 7 | S27: 10 | T27: =SUM(M27:S27) -> 370 | Z27: =M27+2 -> 194 | AA27: =N27 -> 8 | AB27: =O27 -> 0 | AC27: =P27 -> 118 | AD27: =Q27 -> 35 | AE27: =R27 -> 7 | AF27: =S27 -> 10 | AG27: =SUM(Z27:AF27) -> 372 | AH27: =Z27-M27 -> 2 | AI27: =AA27-N27 -> 0 | AJ27: =AB27-O27 -> 0 | AK27: =AC27-P27 -> 0 | AL27: =AD27-Q27 -> 0 | AM27: =AE27-R27 -> 0 | AN27: =AF27-S27 -> 0 | AO27: =AG27-T27 -> 2 | AT27: =VLOOKUP(#REF!,All!$B$4:$S$8977,4,FALSE) -> #REF! | AU27: =VLOOKUP(#REF!,All!$B$4:$S$8977,5,FALSE) -> #REF!
A28: =1+A27 -> 25 | B28: 26 | C28: ឯម | D28: សោភា | E28: Em | F28: Sophea | G28: M | H28: 30171 | I28: 41568 | J28: ADMINISTRATION | K28: GA | L28: Leader GA | M28: 202 | N28: =ROUNDDOWN(INT($N$1-I28-16)/365,0)+1 -> 9 | O28: 60 | P28: 395 | Q28: 71 | R28: 7 | S28: 10 | T28: =SUM(M28:S28) -> 754 | Z28: =M28+2 -> 204 | AA28: =N28 -> 9 | AB28: =O28 -> 60 | AC28: =P28 -> 395 | AD28: =Q28 -> 71 | AE28: =R28 -> 7 | AF28: =S28 -> 10 | AG28: =SUM(Z28:AF28) -> 756 | AH28: =Z28-M28 -> 2 | AI28: =AA28-N28 -> 0 | AJ28: =AB28-O28 -> 0 | AK28: =AC28-P28 -> 0 | AL28: =AD28-Q28 -> 0 | AM28: =AE28-R28 -> 0 | AN28: =AF28-S28 -> 0 | AO28: =AG28-T28 -> 2 | AT28: =VLOOKUP(#REF!,All!$B$4:$S$8977,4,FALSE) -> #REF! | AU28: =VLOOKUP(#REF!,All!$B$4:$S$8977,5,FALSE) -> #REF!
A29: =1+A28 -> 26 | B29: 200 | C29: អ៊ុំ | D29: ចន្ថា | E29: OUM | F29: CHANTHA | G29: M | H29: 29800 | I29: 41694 | J29: Production | K29: Mechanic in line | L29: Leader Mechanic | M29: 192 | N29: =ROUNDDOWN(INT($N$1-I29-16)/365,0)+1 -> 8 | O29: 20 | P29: 295 | Q29: 0 | R29: 7 | S29: 10 | T29: =SUM(M29:S29) -> 532 | Z29: =M29+2 -> 194 | AA29: =N29 -> 8 | AB29: =O29 -> 20 | AC29: =P29 -> 295 | AD29: =Q29 -> 0 | AE29: =R29 -> 7 | AF29: =S29 -> 10 | AG29: =SUM(Z29:AF29) -> 534 | AH29: =Z29-M29 -> 2 | AI29: =AA29-N29 -> 0 | AJ29: =AB29-O29 -> 0 | AK29: =AC29-P29 -> 0 | AL29: =AD29-Q29 -> 0 | AM29: =AE29-R29 -> 0 | AN29: =AF29-S29 -> 0 | AO29: =AG29-T29 -> 2 | AT29: =VLOOKUP(#REF!,All!$B$4:$S$8977,4,FALSE) -> #REF! | AU29: =VLOOKUP(#REF!,All!$B$4:$S$8977,5,FALSE) -> #REF!
A30: =1+A29 -> 27 | B30: 176 | C30: ឃុំ | D30: ផល្លី | E30: khom | F30: pholy | G30: F | H30: 29575 | I30: 41683 | J30: Production | K30: Line15 | L30: Sewing operator | M30: 192 | N30: =ROUNDDOWN(INT($N$1-I30-16)/365,0)+1 -> 8 | O30: 25 | P30: 0 | Q30: 0 | R30: 7 | S30: 10 | T30: =SUM(M30:S30) -> 242 | Z30: =M30+2 -> 194 | AA30: =N30 -> 8 | AB30: =O30 -> 25 | AC30: =P30 -> 0 | AD30: =Q30 -> 0 | AE30: =R30 -> 7 | AF30: =S30 -> 10 | AG30: =SUM(Z30:AF30) -> 244 | AH30: =Z30-M30 -> 2 | AI30: =AA30-N30 -> 0 | AJ30: =AB30-O30 -> 0 | AK30: =AC30-P30 -> 0 | AL30: =AD30-Q30 -> 0 | AM30: =AE30-R30 -> 0 | AN30: =AF30-S30 -> 0 | AO30: =AG30-T30 -> 2 | AT30: =VLOOKUP(#REF!,All!$B$4:$S$8977,4,FALSE) -> #REF! | AU30: =VLOOKUP(#REF!,All!$B$4:$S$8977,5,FALSE) -> #REF!
A31: =1+A30 -> 28 | B31: 224 | C31: ជឿន | D31: រឿម | E31: Choeun | F31: Roeum | G31: F | H31: 28491 | I31: 41702 | J31: Production | K31: Line2 | L31: Sewing operator | M31: 192 | N31: =ROUNDDOWN(INT($N$1-I31-16)/365,0)+1 -> 8 | O31: 20 | P31: 0 | Q31: 0 | R31: 7 | S31: 10 | T31: =SUM(M31:S31) -> 237 | Z31: =M31+2 -> 194 | AA31: =N31 -> 8 | AB31: =O31 -> 20 | AC31: =P31 -> 0 | AD31: =Q31 -> 0 | AE31: =R31 -> 7 | AF31: =S31 -> 10 | AG31: =SUM(Z31:AF31) -> 239 | AH31: =Z31-M31 -> 2 | AI31: =AA31-N31 -> 0 | AJ31: =AB31-O31 -> 0 | AK31: =AC31-P31 -> 0 | AL31: =AD31-Q31 -> 0 | AM31: =AE31-R31 -> 0 | AN31: =AF31-S31 -> 0 | AO31: =AG31-T31 -> 2 | AT31: =VLOOKUP(#REF!,All!$B$4:$S$8977,4,FALSE) -> #REF! | AU31: =VLOOKUP(#REF!,All!$B$4:$S$8977,5,FALSE) -> #REF!
A32: =1+A31 -> 29 | B32: 226 | C32: រស់ | D32: ផល្លី | E32: Ros | F32: Poly | G32: F | H32: 30275 | I32: 41702 | J32: Production | K32: Line2 | L32: Sewing operator | M32: 192 | N32: =ROUNDDOWN(INT($N$1-I32-16)/365,0)+1 -> 8 | O32: 20 | P32: 0 | Q32: 0 | R32: 7 | S32: 10 | T32: =SUM(M32:S32) -> 237 | Z32: =M32+2 -> 194 | AA32: =N32 -> 8 | AB32: =O32 -> 20 | AC32: =P32 -> 0 | AD32: =Q32 -> 0 | AE32: =R32 -> 7 | AF32: =S32 -> 10 | AG32: =SUM(Z32:AF32) -> 239 | AH32: =Z32-M32 -> 2 | AI32: =AA32-N32 -> 0 | AJ32: =AB32-O32 -> 0 | AK32: =AC32-P32 -> 0 | AL32: =AD32-Q32 -> 0 | AM32: =AE32-R32 -> 0 | AN32: =AF32-S32 -> 0 | AO32: =AG32-T32 -> 2
A33: =1+A32 -> 30 | B33: 271 | C33: វុន | D33: តាំង | E33: VUN | F33: TAING | G33: F | H33: 29064 | I33: 41730 | J33: Production | K33: Line17 | L33: Sewing operator | M33: 192 | N33: =ROUNDDOWN(INT($N$1-I33-16)/365,0)+1 -> 8 | O33: 20 | P33: 0 | Q33: 0 | R33: 7 | S33: 10 | T33: =SUM(M33:S33) -> 237 | Z33: =M33+2 -> 194 | AA33: =N33 -> 8 | AB33: =O33 -> 20 | AC33: =P33 -> 0 | AD33: =Q33 -> 0 | AE33: =R33 -> 7 | AF33: =S33 -> 10 | AG33: =SUM(Z33:AF33) -> 239 | AH33: =Z33-M33 -> 2 | AI33: =AA33-N33 -> 0 | AJ33: =AB33-O33 -> 0 | AK33: =AC33-P33 -> 0 | AL33: =AD33-Q33 -> 0 | AM33: =AE33-R33 -> 0 | AN33: =AF33-S33 -> 0 | AO33: =AG33-T33 -> 2
A34: =1+A33 -> 31 | B34: 283 | C34: កែវ | D34: ពុទ្ធា | E34: KEO | F34: PUTHEA | G34: F | H34: 34151 | I34: 41750 | J34: Production | K34: Line21 | L34: Sewing operator | M34: 192 | N34: =ROUNDDOWN(INT($N$1-I34-16)/365,0)+1 -> 8 | O34: 20 | P34: 0 | Q34: 0 | R34: 7 | S34: 10 | T34: =SUM(M34:S34) -> 237 | Z34: =M34+2 -> 194 | AA34: =N34 -> 8 | AB34: =O34 -> 20 | AC34: =P34 -> 0 | AD34: =Q34 -> 0 | AE34: =R34 -> 7 | AF34: =S34 -> 10 | AG34: =SUM(Z34:AF34) -> 239 | AH34: =Z34-M34 -> 2 | AI34: =AA34-N34 -> 0 | AJ34: =AB34-O34 -> 0 | AK34: =AC34-P34 -> 0 | AL34: =AD34-Q34 -> 0 | AM34: =AE34-R34 -> 0 | AN34: =AF34-S34 -> 0 | AO34: =AG34-T34 -> 2
A35: =1+A34 -> 32 | B35: 286 | C35: ម៉ិល | D35: វី | E35: MIL | F35: VY | G35: F | H35: 26674 | I35: 41751 | J35: Production | K35: Line21 | L35: Sewing operator | M35: 192 | N35: =ROUNDDOWN(INT($N$1-I35-16)/365,0)+1 -> 8 | O35: 20 | P35: 0 | Q35: 0 | R35: 7 | S35: 10 | T35: =SUM(M35:S35) -> 237 | Z35: =M35+2 -> 194 | AA35: =N35 -> 8 | AB35: =O35 -> 20 | AC35: =P35 -> 0 | AD35: =Q35 -> 0 | AE35: =R35 -> 7 | AF35: =S35 -> 10 | AG35: =SUM(Z35:AF35) -> 239 | AH35: =Z35-M35 -> 2 | AI35: =AA35-N35 -> 0 | AJ35: =AB35-O35 -> 0 | AK35: =AC35-P35 -> 0 | AL35: =AD35-Q35 -> 0 | AM35: =AE35-R35 -> 0 | AN35: =AF35-S35 -> 0 | AO35: =AG35-T35 -> 2
A36: =1+A35 -> 33 | B36: 312 | C36: នាក់ | D36: នួន | E36: NAK | F36: NGUON | G36: F | H36: 30906 | I36: 41754 | J36: Production | K36: Line21 | L36: Sewing operator | M36: 192 | N36: =ROUNDDOWN(INT($N$1-I36-16)/365,0)+1 -> 8 | O36: 20 | P36: 0 | Q36: 0 | R36: 7 | S36: 10 | T36: =SUM(M36:S36) -> 237 | Z36: =M36+2 -> 194 | AA36: =N36 -> 8 | AB36: =O36 -> 20 | AC36: =P36 -> 0 | AD36: =Q36 -> 0 | AE36: =R36 -> 7 | AF36: =S36 -> 10 | AG36: =SUM(Z36:AF36) -> 239 | AH36: =Z36-M36 -> 2 | AI36: =AA36-N36 -> 0 | AJ36: =AB36-O36 -> 0 | AK36: =AC36-P36 -> 0 | AL36: =AD36-Q36 -> 0 | AM36: =AE36-R36 -> 0 | AN36: =AF36-S36 -> 0 | AO36: =AG36-T36 -> 2
A37: =1+A36 -> 34 | B37: 316 | C37: រិន | D37: ចាន់ថា | E37: RIN | F37: CHANTHA | G37: F | H37: 34981 | I37: 41755 | J37: Production | K37: Warehouse Trims | L37: accessory assistant | M37: 192 | N37: =ROUNDDOWN(INT($N$1-I37-16)/365,0)+1 -> 8 | O37: 20 | P37: 20 | Q37: 0 | R37: 7 | S37: 10 | T37: =SUM(M37:S37) -> 257 | Z37: =M37+2 -> 194 | AA37: =N37 -> 8 | AB37: =O37 -> 20 | AC37: =P37 -> 20 | AD37: =Q37 -> 0 | AE37: =R37 -> 7 | AF37: =S37 -> 10 | AG37: =SUM(Z37:AF37) -> 259 | AH37: =Z37-M37 -> 2 | AI37: =AA37-N37 -> 0 | AJ37: =AB37-O37 -> 0 | AK37: =AC37-P37 -> 0 | AL37: =AD37-Q37 -> 0 | AM37: =AE37-R37 -> 0 | AN37: =AF37-S37 -> 0 | AO37: =AG37-T37 -> 2
A38: =1+A37 -> 35 | B38: 326 | C38: ផង់ | D38: ហៃ | E38: PHANG | F38: HEY | G38: F | H38: 30929 | I38: 41762 | J38: Production | K38: Line1 | L38: Sewing operator | M38: 192 | N38: =ROUNDDOWN(INT($N$1-I38-16)/365,0)+1 -> 8 | O38: 20 | P38: 0 | Q38: 0 | R38: 7 | S38: 10 | T38: =SUM(M38:S38) -> 237 | Z38: =M38+2 -> 194 | AA38: =N38 -> 8 | AB38: =O38 -> 20 | AC38: =P38 -> 0 | AD38: =Q38 -> 0 | AE38: =R38 -> 7 | AF38: =S38 -> 10 | AG38: =SUM(Z38:AF38) -> 239 | AH38: =Z38-M38 -> 2 | AI38: =AA38-N38 -> 0 | AJ38: =AB38-O38 -> 0 | AK38: =AC38-P38 -> 0 | AL38: =AD38-Q38 -> 0 | AM38: =AE38-R38 -> 0 | AN38: =AF38-S38 -> 0 | AO38: =AG38-T38 -> 2
A39: =1+A38 -> 36 | B39: 351 | C39: និត | D39: ស្រីនាង | E39: NIT | F39: SREYNEANG | G39: F | H39: 32567 | I39: 41766 | J39: Production | K39: Line20 | L39: Sewing operator | M39: 192 | N39: =ROUNDDOWN(INT($N$1-I39-16)/365,0)+1 -> 8 | O39: 20 | P39: 5 | Q39: 0 | R39: 7 | S39: 10 | T39: =SUM(M39:S39) -> 242 | Z39: =M39+2 -> 194 | AA39: =N39 -> 8 | AB39: =O39 -> 20 | AC39: =P39 -> 5 | AD39: =Q39 -> 0 | AE39: =R39 -> 7 | AF39: =S39 -> 10 | AG39: =SUM(Z39:AF39) -> 244 | AH39: =Z39-M39 -> 2 | AI39: =AA39-N39 -> 0 | AJ39: =AB39-O39 -> 0 | AK39: =AC39-P39 -> 0 | AL39: =AD39-Q39 -> 0 | AM39: =AE39-R39 -> 0 | AN39: =AF39-S39 -> 0 | AO39: =AG39-T39 -> 2
A40: =1+A39 -> 37 | B40: 372 | C40: លី | D40: ប៊ុនរិទ្ធ | E40: LY | F40: BONRETH | G40: M | H40: 30348 | I40: 41765 | J40: ADMINISTRATION | K40: ME | L40: Leader Maiternance | M40: 192 | N40: =ROUNDDOWN(INT($N$1-I40-16)/365,0)+1 -> 8 | O40: 85 | P40: 400 | Q40: 0 | R40: 7 | S40: 10 | T40: =SUM(M40:S40) -> 702 | Z40: =M40+2 -> 194 | AA40: =N40 -> 8 | AB40: =O40 -> 85 | AC40: =P40 -> 400 | AD40: =Q40 -> 0 | AE40: =R40 -> 7 | AF40: =S40 -> 10 | AG40: =SUM(Z40:AF40) -> 704 | AH40: =Z40-M40 -> 2 | AI40: =AA40-N40 -> 0 | AJ40: =AB40-O40 -> 0 | AK40: =AC40-P40 -> 0 | AL40: =AD40-Q40 -> 0 | AM40: =AE40-R40 -> 0 | AN40: =AF40-S40 -> 0 | AO40: =AG40-T40 -> 2
...

Sheet Office
A1: ល.រ | B1: Factory ID | C1: គោត្តនាម | D1: នាម | E1: គោត្តនាមឡាតាំង | F1: នាមឡាតាំង | G1: ភេទ | H1: ថ្ងៃខែឆ្នាំកំណើត | I1: កាលបរិ. ចូលធ្វើការ | J1: ផ្នែក | K1: ក្រុម | L1: តួនាទី | M1: Salary Report 2021 | U1: Adjust amount | V1: Adjust Date | W1: Evaluator | X1: 2022 Total Marks | Y1: With Comment | Z1: Salary Report 2022
A2: Nº | B2: Factory ID | C2: Khmer Sure name | D2: Khmer Name | E2: English Sure name | F2: Khmer Name | G2: Sex | H2: Birth of Date | I2: Join Date | J2: Department | K2: Group | L2: Position | M2: Basic | N2: Seniority | O2: Skill | P2: Position | Q2: Language | R2: Housing &Transportation | S2: Motivation | T2: Total | U2: 調動金額 | V2: 調動日期 | W2: 評核人 | X2: 2022總分 | Y2: 意見 | Z2: Basic | AA2: Seniority | AB2: Skill | AC2: Position | AD2: Language | AE2: Housing &Transportation | AF2: Motivation | AG2: Total
A3: 排序 | B3: 工號 | E3: 姓名 | G3: 性別 | H3: 生日 | I3: 入職日期 | J3: 部門 | K3: 組別 | L3: 崗位名稱 | M3: 底薪 | N3: 工齡 | O3: 技能 | P3: 職位 | Q3: 語言 | R3: 房屋/交通 | S3: 全勤 | T3: 2021薪資總額 | U3: 調動金額 | V3: 調動日期 | W3: 評核人 | X3: 2022總分 | Y3: 意見 | Z3: 底薪 | AA3: 工齡 | AB3: 技能 | AC3: 職位 | AD3: 語言 | AE3: 房屋/交通 | AF3: 全勤 | AG3: 2022薪資總額
A4: =1 -> 1 | B4: 2037 | C4: =VLOOKUP(B4,All!$B$4:$S$8977,2,FALSE) -> សៀង | D4: =VLOOKUP(B4,All!$B$4:$S$89977,3,FALSE) -> វាសនា | E4: =VLOOKUP(B4,All!$B$4:$S$8977,4,FALSE) -> SEANG | F4: =VLOOKUP(B4,All!$B$4:$S$8977,5,FALSE) -> VEASNA | G4: =VLOOKUP(B4,All!$B$4:$S$8977,6,FALSE) -> M | H4: =VLOOKUP(B4,All!$B$4:$S$8977,7,FALSE) -> 31810 | I4: =VLOOKUP(B4,All!$B$4:$S$8977,8,FALSE) -> 42917 | J4: =VLOOKUP(B4,All!$B$4:$S$8977,9,FALSE) -> Shipping | K4: =VLOOKUP(B4,All!$B$4:$S$8977,10,FALSE) -> Export | L4: =VLOOKUP(B4,All!$B$4:$S$8977,11,FALSE) -> assistant | M4: =VLOOKUP(B4,All!$B$4:$S$8977,12,FALSE) -> 192 | N4: =VLOOKUP(B4,All!$B$4:$S$8977,13,FALSE) -> 5 | O4: =VLOOKUP(B4,All!$B$4:$S$8977,14,FALSE) -> 20 | P4: =VLOOKUP(B4,All!$B$4:$S$8977,15,FALSE) -> 200 | Q4: =VLOOKUP(B4,All!$B$4:$S$8977,16,FALSE) -> 50 | R4: 7 | S4: 10 | T4: =SUM(M4:S4) -> 484 | U4: 30 | V4: 44562 | W4: Jerry | Y4: 出口助理 | Z4: =M4+AH4 -> 194 | AA4: =N4 -> 5 | AB4: =O4 -> 20 | AC4: =P4+U4 -> 230 | AD4: =Q4 -> 50 | AE4: =R4 -> 7 | AF4: =S4 -> 10 | AG4: =SUM(Z4:AF4) -> 516 | AH4: 2 | AI4: =AA4-N4 -> 0 | AJ4: =AB4-O4 -> 0 | AK4: =AC4-P4 -> 30 | AL4: =AD4-Q4 -> 0 | AM4: =AE4-R4 -> 0 | AN4: =AF4-S4 -> 0 | AO4: =AG4-T4 -> 32
A5: =1+A4 -> 2 | B5: 3083 | C5: =VLOOKUP(B5,All!$B$4:$S$8977,2,FALSE) -> សន់ | D5: =VLOOKUP(B5,All!$B$4:$S$89977,3,FALSE) -> សុរ៉ាន់ដា | E5: =VLOOKUP(B5,All!$B$4:$S$8977,4,FALSE) -> Son | F5: =VLOOKUP(B5,All!$B$4:$S$8977,5,FALSE) -> Sorannda | G5: =VLOOKUP(B5,All!$B$4:$S$8977,6,FALSE) -> M | H5: =VLOOKUP(B5,All!$B$4:$S$8977,7,FALSE) -> 34992 | I5: =VLOOKUP(B5,All!$B$4:$S$8977,8,FALSE) -> 43620 | J5: IT | L5: =VLOOKUP(B5,All!$B$4:$S$8977,11,FALSE) -> IT specialist | M5: =VLOOKUP(B5,All!$B$4:$S$8977,12,FALSE) -> 192 | N5: =VLOOKUP(B5,All!$B$4:$S$8977,13,FALSE) -> 3 | O5: =VLOOKUP(B5,All!$B$4:$S$8977,14,FALSE) -> 163 | P5: =VLOOKUP(B5,All!$B$4:$S$8977,15,FALSE) -> 208 | Q5: =VLOOKUP(B5,All!$B$4:$S$8977,16,FALSE) -> 10 | R5: 7 | S5: 10 | T5: =SUM(M5:S5) -> 593 | U5: 30 | V5: 44562 | W5: Jerry | Y5: IT專員 | Z5: =M5+AH5 -> 194 | AA5: =N5 -> 3 | AB5: =O5 -> 163 | AC5: =P5+U5 -> 238 | AD5: =Q5 -> 10 | AE5: =R5 -> 7 | AF5: =S5 -> 10 | AG5: =SUM(Z5:AF5) -> 625 | AH5: 2 | AI5: =AA5-N5 -> 0 | AJ5: =AB5-O5 -> 0 | AK5: =AC5-P5 -> 30 | AL5: =AD5-Q5 -> 0 | AM5: =AE5-R5 -> 0 | AN5: =AF5-S5 -> 0 | AO5: =AG5-T5 -> 32
A6: =1+A5 -> 3 | B6: 3426 | C6: =VLOOKUP(B6,All!$B$4:$S$8977,2,FALSE) -> ប៉ុក | D6: =VLOOKUP(B6,All!$B$4:$S$89977,3,FALSE) -> ដាវុទ្ធា | E6: =VLOOKUP(B6,All!$B$4:$S$8977,4,FALSE) -> POK | F6: =VLOOKUP(B6,All!$B$4:$S$8977,5,FALSE) -> DAVUTHEA | G6: =VLOOKUP(B6,All!$B$4:$S$8977,6,FALSE) -> M | H6: =VLOOKUP(B6,All!$B$4:$S$8977,7,FALSE) -> 34765 | I6: =VLOOKUP(B6,All!$B$4:$S$8977,8,FALSE) -> 43771 | J6: =VLOOKUP(B6,All!$B$4:$S$8977,9,FALSE) -> Production | K6: =VLOOKUP(B6,All!$B$4:$S$8977,10,FALSE) -> Finish good | L6: =VLOOKUP(B6,All!$B$4:$S$8977,11,FALSE) -> assistant | M6: =VLOOKUP(B6,All!$B$4:$S$8977,12,FALSE) -> 192 | N6: =VLOOKUP(B6,All!$B$4:$S$8977,13,FALSE) -> 3 | O6: =VLOOKUP(B6,All!$B$4:$S$8977,14,FALSE) -> 20 | P6: =VLOOKUP(B6,All!$B$4:$S$8977,15,FALSE) -> 30 | Q6: =VLOOKUP(B6,All!$B$4:$S$8977,16,FALSE) -> 0 | R6: 7 | S6: 10 | T6: =SUM(M6:S6) -> 262 | U6: 15 | V6: 44562 | W6: Jerry | Y6: 成品助理 | Z6: =M6+AH6 -> 194 | AA6: =N6 -> 3 | AB6: =O6 -> 20 | AC6: =P6+U6 -> 45 | AD6: =Q6 -> 0 | AE6: =R6 -> 7 | AF6: =S6 -> 10 | AG6: =SUM(Z6:AF6) -> 279 | AH6: 2 | AI6: =AA6-N6 -> 0 | AJ6: =AB6-O6 -> 0 | AK6: =AC6-P6 -> 15 | AL6: =AD6-Q6 -> 0 | AM6: =AE6-R6 -> 0 | AN6: =AF6-S6 -> 0 | AO6: =AG6-T6 -> 17
A7: =1+A6 -> 4 | B7: 4060 | C7: =VLOOKUP(B7,All!$B$4:$S$8977,2,FALSE) -> លី | D7: =VLOOKUP(B7,All!$B$4:$S$89977,3,FALSE) -> ឡេងចេង | E7: =VLOOKUP(B7,All!$B$4:$S$8977,4,FALSE) -> LY | F7: =VLOOKUP(B7,All!$B$4:$S$8977,5,FALSE) -> LENGCHENG | G7: =VLOOKUP(B7,All!$B$4:$S$8977,6,FALSE) -> F | H7: =VLOOKUP(B7,All!$B$4:$S$8977,7,FALSE) -> 33159 | I7: =VLOOKUP(B7,All!$B$4:$S$8977,8,FALSE) -> 43842 | J7: =VLOOKUP(B7,All!$B$4:$S$8977,9,FALSE) -> Production | K7: =VLOOKUP(B7,All!$B$4:$S$8977,10,FALSE) -> Finish good | L7: =VLOOKUP(B7,All!$B$4:$S$8977,11,FALSE) -> assistant | M7: =VLOOKUP(B7,All!$B$4:$S$8977,12,FALSE) -> 192 | N7: =VLOOKUP(B7,All!$B$4:$S$8977,13,FALSE) -> 3 | O7: =VLOOKUP(B7,All!$B$4:$S$8977,14,FALSE) -> 20 | P7: =VLOOKUP(B7,All!$B$4:$S$8977,15,FALSE) -> 43 | Q7: =VLOOKUP(B7,All!$B$4:$S$8977,16,FALSE) -> 20 | R7: 7 | S7: 10 | T7: =SUM(M7:S7) -> 295 | U7: 15 | V7: 44562 | W7: Jerry | Y7: 成品助理 | Z7: =M7+AH7 -> 194 | AA7: =N7 -> 3 | AB7: =O7 -> 20 | AC7: =P7+U7 -> 58 | AD7: =Q7 -> 20 | AE7: =R7 -> 7 | AF7: =S7 -> 10 | AG7: =SUM(Z7:AF7) -> 312 | AH7: 2 | AI7: =AA7-N7 -> 0 | AJ7: =AB7-O7 -> 0 | AK7: =AC7-P7 -> 15 | AL7: =AD7-Q7 -> 0 | AM7: =AE7-R7 -> 0 | AN7: =AF7-S7 -> 0 | AO7: =AG7-T7 -> 17
A8: =1+A7 -> 5 | B8: 2242 | C8: =VLOOKUP(B8,All!$B$4:$S$8977,2,FALSE) -> វ៉ន | D8: =VLOOKUP(B8,All!$B$4:$S$89977,3,FALSE) -> សុភក្តិ | E8: =VLOOKUP(B8,All!$B$4:$S$8977,4,FALSE) -> VORN | F8: =VLOOKUP(B8,All!$B$4:$S$8977,5,FALSE) -> SOPHEAK | G8: =VLOOKUP(B8,All!$B$4:$S$8977,6,FALSE) -> F | H8: =VLOOKUP(B8,All!$B$4:$S$8977,7,FALSE) -> 34837 | I8: =VLOOKUP(B8,All!$B$4:$S$8977,8,FALSE) -> 42962 | J8: =VLOOKUP(B8,All!$B$4:$S$8977,9,FALSE) -> Production | K8: =VLOOKUP(B8,All!$B$4:$S$8977,10,FALSE) -> PC | L8: =VLOOKUP(B8,All!$B$4:$S$8977,11,FALSE) -> PC assistant | M8: =VLOOKUP(B8,All!$B$4:$S$8977,12,FALSE) -> 192 | N8: =VLOOKUP(B8,All!$B$4:$S$8977,13,FALSE) -> 5 | O8: =VLOOKUP(B8,All!$B$4:$S$8977,14,FALSE) -> 0 | P8: =VLOOKUP(B8,All!$B$4:$S$8977,15,FALSE) -> 153 | Q8: =VLOOKUP(B8,All!$B$4:$S$8977,16,FALSE) -> 40 | R8: 7 | S8: 10 | T8: =SUM(M8:S8) -> 407 | U8: 15 | V8: 44562 | W8: Jerry | Y8: 生管助理 | Z8: =M8+AH8 -> 194 | AA8: =N8 -> 5 | AB8: =O8 -> 0 | AC8: =P8+U8 -> 168 | AD8: =Q8 -> 40 | AE8: =R8 -> 7 | AF8: =S8 -> 10 | AG8: =SUM(Z8:AF8) -> 424 | AH8: 2 | AI8: =AA8-N8 -> 0 | AJ8: =AB8-O8 -> 0 | AK8: =AC8-P8 -> 15 | AL8: =AD8-Q8 -> 0 | AM8: =AE8-R8 -> 0 | AN8: =AF8-S8 -> 0 | AO8: =AG8-T8 -> 17
A9: =1+A8 -> 6 | B9: 2612 | C9: =VLOOKUP(B9,All!$B$4:$S$8977,2,FALSE) -> អ៊ុត | D9: =VLOOKUP(B9,All!$B$4:$S$89977,3,FALSE) -> សូរិយា | E9: =VLOOKUP(B9,All!$B$4:$S$8977,4,FALSE) -> UT | F9: =VLOOKUP(B9,All!$B$4:$S$8977,5,FALSE) -> SORIYA | G9: =VLOOKUP(B9,All!$B$4:$S$8977,6,FALSE) -> F | H9: =VLOOKUP(B9,All!$B$4:$S$8977,7,FALSE) -> 36742 | I9: =VLOOKUP(B9,All!$B$4:$S$8977,8,FALSE) -> 43474 | J9: =VLOOKUP(B9,All!$B$4:$S$8977,9,FALSE) -> Production | K9: =VLOOKUP(B9,All!$B$4:$S$8977,10,FALSE) -> PC | L9: =VLOOKUP(B9,All!$B$4:$S$8977,11,FALSE) -> PC clerk | M9: =VLOOKUP(B9,All!$B$4:$S$8977,12,FALSE) -> 192 | N9: =VLOOKUP(B9,All!$B$4:$S$8977,13,FALSE) -> 4 | O9: =VLOOKUP(B9,All!$B$4:$S$8977,14,FALSE) -> 0 | P9: =VLOOKUP(B9,All!$B$4:$S$8977,15,FALSE) -> 61 | Q9: =VLOOKUP(B9,All!$B$4:$S$8977,16,FALSE) -> 0 | R9: 7 | S9: 10 | T9: =SUM(M9:S9) -> 274 | U9: 10 | V9: 44562 | W9: Jerry | Y9: 生管 | Z9: =M9+AH9 -> 194 | AA9: =N9 -> 4 | AB9: =O9 -> 0 | AC9: =P9+U9 -> 71 | AD9: =Q9 -> 0 | AE9: =R9 -> 7 | AF9: =S9 -> 10 | AG9: =SUM(Z9:AF9) -> 286 | AH9: 2 | AI9: =AA9-N9 -> 0 | AJ9: =AB9-O9 -> 0 | AK9: =AC9-P9 -> 10 | AL9: =AD9-Q9 -> 0 | AM9: =AE9-R9 -> 0 | AN9: =AF9-S9 -> 0 | AO9: =AG9-T9 -> 12
A10: =1+A9 -> 7 | B10: 5055 | C10: =VLOOKUP(B10,All!$B$4:$S$8977,2,FALSE) -> វ៉ន | D10: =VLOOKUP(B10,All!$B$4:$S$89977,3,FALSE) -> គីមហុង | E10: =VLOOKUP(B10,All!$B$4:$S$8977,4,FALSE) -> VORN | F10: =VLOOKUP(B10,All!$B$4:$S$8977,5,FALSE) -> KIMHONG | G10: =VLOOKUP(B10,All!$B$4:$S$8977,6,FALSE) -> M | H10: =VLOOKUP(B10,All!$B$4:$S$8977,7,FALSE) -> 36751 | I10: =VLOOKUP(B10,All!$B$4:$S$8977,8,FALSE) -> 44147 | J10: =VLOOKUP(B10,All!$B$4:$S$8977,9,FALSE) -> Production | K10: =VLOOKUP(B10,All!$B$4:$S$8977,10,FALSE) -> PC | L10: =VLOOKUP(B10,All!$B$4:$S$8977,11,FALSE) -> PC clerk | M10: =VLOOKUP(B10,All!$B$4:$S$8977,12,FALSE) -> 192 | N10: =VLOOKUP(B10,All!$B$4:$S$8977,13,FALSE) -> 2 | O10: =VLOOKUP(B10,All!$B$4:$S$8977,14,FALSE) -> 0 | P10: =VLOOKUP(B10,All!$B$4:$S$8977,15,FALSE) -> 18 | Q10: =VLOOKUP(B10,All!$B$4:$S$8977,16,FALSE) -> 0 | R10: 7 | S10: 10 | T10: =SUM(M10:S10) -> 229 | U10: 10 | V10: 44562 | W10: Jerry | Y10: 生管 | Z10: =M10+AH10 -> 194 | AA10: =N10 -> 2 | AB10: =O10 -> 0 | AC10: =P10+U10 -> 28 | AD10: =Q10 -> 0 | AE10: =R10 -> 7 | AF10: =S10 -> 10 | AG10: =SUM(Z10:AF10) -> 241 | AH10: 2 | AI10: =AA10-N10 -> 0 | AJ10: =AB10-O10 -> 0 | AK10: =AC10-P10 -> 10 | AL10: =AD10-Q10 -> 0 | AM10: =AE10-R10 -> 0 | AN10: =AF10-S10 -> 0 | AO10: =AG10-T10 -> 12
A11: =1+A10 -> 8 | B11: 18 | C11: =VLOOKUP(B11,All!$B$4:$S$8977,2,FALSE) -> ស្រី | D11: =VLOOKUP(B11,All!$B$4:$S$89977,3,FALSE) -> ច័ន្ទថុនា | E11: =VLOOKUP(B11,All!$B$4:$S$8977,4,FALSE) -> Srey | F11: =VLOOKUP(B11,All!$B$4:$S$8977,5,FALSE) -> Chanthuna | G11: =VLOOKUP(B11,All!$B$4:$S$8977,6,FALSE) -> M | H11: =VLOOKUP(B11,All!$B$4:$S$8977,7,FALSE) -> 33771 | I11: =VLOOKUP(B11,All!$B$4:$S$8977,8,FALSE) -> 41577 | J11: Production | K11: Marker | L11: =VLOOKUP(B11,All!$B$4:$S$8977,11,FALSE) -> Marker technicial | M11: =VLOOKUP(B11,All!$B$4:$S$8977,12,FALSE) -> 262 | N11: =VLOOKUP(B11,All!$B$4:$S$8977,13,FALSE) -> 9 | O11: =VLOOKUP(B11,All!$B$4:$S$8977,14,FALSE) -> 20 | P11: =VLOOKUP(B11,All!$B$4:$S$8977,15,FALSE) -> 72 | Q11: =VLOOKUP(B11,All!$B$4:$S$8977,16,FALSE) -> 66 | R11: 7 | S11: 10 | T11: =SUM(M11:S11) -> 446 | U11: 40 | V11: 44562 | W11: Jerry | Y11: 馬克技術員 | Z11: =M11+AH11 -> 264 | AA11: =N11 -> 9 | AB11: =O11 -> 20 | AC11: =P11+U11 -> 112 | AD11: =Q11 -> 66 | AE11: =R11 -> 7 | AF11: =S11 -> 10 | AG11: =SUM(Z11:AF11) -> 488 | AH11: 2 | AI11: =AA11-N11 -> 0 | AJ11: =AB11-O11 -> 0 | AK11: =AC11-P11 -> 40 | AL11: =AD11-Q11 -> 0 | AM11: =AE11-R11 -> 0 | AN11: =AF11-S11 -> 0 | AO11: =AG11-T11 -> 42
A12: =1+A11 -> 9 | B12: 1411 | C12: =VLOOKUP(B12,All!$B$4:$S$8977,2,FALSE) -> រូ | D12: =VLOOKUP(B12,All!$B$4:$S$89977,3,FALSE) -> និច | E12: =VLOOKUP(B12,All!$B$4:$S$8977,4,FALSE) -> Ro | F12: =VLOOKUP(B12,All!$B$4:$S$8977,5,FALSE) -> Nich | G12: =VLOOKUP(B12,All!$B$4:$S$8977,6,FALSE) -> F | H12: =VLOOKUP(B12,All!$B$4:$S$8977,7,FALSE) -> 35831 | I12: =VLOOKUP(B12,All!$B$4:$S$8977,8,FALSE) -> 42343 | J12: Production | K12: Sample | L12: =VLOOKUP(B12,All!$B$4:$S$8977,11,FALSE) -> Sample Coordinator | M12: =VLOOKUP(B12,All!$B$4:$S$8977,12,FALSE) -> 192 | N12: =VLOOKUP(B12,All!$B$4:$S$8977,13,FALSE) -> 7 | O12: =VLOOKUP(B12,All!$B$4:$S$8977,14,FALSE) -> 20 | P12: =VLOOKUP(B12,All!$B$4:$S$8977,15,FALSE) -> 85 | Q12: =VLOOKUP(B12,All!$B$4:$S$8977,16,FALSE) -> 30 | R12: 7 | S12: 10 | T12: =SUM(M12:S12) -> 351 | U12: 40 | V12: 44562 | W12: Jerry | Y12: 樣品安排 | Z12: =M12+AH12 -> 194 | AA12: =N12 -> 7 | AB12: =O12 -> 20 | AC12: =P12+U12 -> 125 | AD12: =Q12 -> 30 | AE12: =R12 -> 7 | AF12: =S12 -> 10 | AG12: =SUM(Z12:AF12) -> 393 | AH12: 2 | AI12: =AA12-N12 -> 0 | AJ12: =AB12-O12 -> 0 | AK12: =AC12-P12 -> 40 | AL12: =AD12-Q12 -> 0 | AM12: =AE12-R12 -> 0 | AN12: =AF12-S12 -> 0 | AO12: =AG12-T12 -> 42
T14: =SUM(T4:T13) -> 3341 | U14: =SUM(U4:U13) -> 205 | AG14: =SUM(AG4:AG13) -> 3564 | AH14: =SUM(AH4:AH13) -> 18 | AJ14: =SUM(AJ4:AJ13) -> 0

Sheet WH F&L
A1: ល.រ | B1: Factory ID | C1: គោត្តនាម | D1: នាម | E1: គោត្តនាមឡាតាំង | F1: នាមឡាតាំង | G1: ភេទ | H1: ថ្ងៃខែឆ្នាំកំណើត | I1: កាលបរិ. ចូលធ្វើការ | J1: ផ្នែក | K1: ក្រុម | L1: តួនាទី | M1: Salary Report 2021 | U1: Adjust amount | V1: Adjust Date | W1: Evaluator | X1: 2022 Total Marks | Y1: With Comment | Z1: Salary Report 2022
A2: Nº | B2: Factory ID | C2: Khmer Sure name | D2: Khmer Name | E2: English Sure name | F2: Khmer Name | G2: Sex | H2: Birth of Date | I2: Join Date | J2: Department | K2: Group | L2: Position | M2: Basic | N2: Seniority | O2: Skill | P2: Position | Q2: Language | R2: Housing &Transportation | S2: Motivation | T2: Total | U2: 調動金額 | V2: 調動日期 | W2: 評核人 | X2: 2022總分 | Y2: 意見 | Z2: Basic | AA2: Seniority | AB2: Skill | AC2: Position | AD2: Language | AE2: Housing &Transportation | AF2: Motivation | AG2: Total
A3: 排序 | B3: 工號 | E3: 姓名 | G3: 性別 | H3: 生日 | I3: 入職日期 | J3: 部門 | K3: 組別 | L3: 崗位名稱 | M3: 底薪 | N3: 工齡 | O3: 技能 | P3: 職位 | Q3: 語言 | R3: 房屋/交通 | S3: 全勤 | T3: 2021薪資總額 | U3: 調動金額 | V3: 調動日期 | W3: 評核人 | X3: 2022總分 | Y3: 意見 | Z3: 底薪 | AA3: 工齡 | AB3: 技能 | AC3: 職位 | AD3: 語言 | AE3: 房屋/交通 | AF3: 全勤 | AG3: 2022薪資總額
A4: =1 -> 1 | B4: 2426 | C4: =VLOOKUP(B4,All!$B$4:$S$8977,2,FALSE) -> ផុន | D4: =VLOOKUP(B4,All!$B$4:$S$89977,3,FALSE) -> ភារ៉ា | E4: =VLOOKUP(B4,All!$B$4:$S$8977,4,FALSE) -> PHON | F4: =VLOOKUP(B4,All!$B$4:$S$8977,5,FALSE) -> PHEARA | G4: =VLOOKUP(B4,All!$B$4:$S$8977,6,FALSE) -> M | H4: =VLOOKUP(B4,All!$B$4:$S$8977,7,FALSE) -> 32516 | I4: =VLOOKUP(B4,All!$B$4:$S$8977,8,FALSE) -> 43222 | J4: =VLOOKUP(B4,All!$B$4:$S$8977,9,FALSE) -> Production | K4: =VLOOKUP(B4,All!$B$4:$S$8977,10,FALSE) -> Warehouse Fabric | L4: =VLOOKUP(B4,All!$B$4:$S$8977,11,FALSE) -> Loader | M4: =VLOOKUP(B4,All!$B$4:$S$8977,12,FALSE) -> 192 | N4: =VLOOKUP(B4,All!$B$4:$S$8977,13,FALSE) -> 4 | O4: =VLOOKUP(B4,All!$B$4:$S$8977,14,FALSE) -> 20 | P4: =VLOOKUP(B4,All!$B$4:$S$8977,15,FALSE) -> 25 | Q4: =VLOOKUP(B4,All!$B$4:$S$8977,16,FALSE) -> 0 | R4: 7 | S4: 10 | T4: =SUM(M4:S4) -> 258 | Z4: =M4+AH4 -> 194 | AA4: =N4 -> 4 | AB4: =O4 -> 20 | AC4: =P4 -> 25 | AD4: =Q4 -> 0 | AE4: =R4 -> 7 | AF4: =S4 -> 10 | AG4: =SUM(Z4:AF4) -> 260 | AH4: 2 | AI4: 0 | AJ4: 0 | AK4: 0 | AL4: 0 | AM4: 0 | AN4: 0 | AO4: 2
A5: =1+A4 -> 2 | B5: 2851 | C5: =VLOOKUP(B5,All!$B$4:$S$8977,2,FALSE) -> ផាង | D5: =VLOOKUP(B5,All!$B$4:$S$89977,3,FALSE) -> ហ៊ុយ | E5: =VLOOKUP(B5,All!$B$4:$S$8977,4,FALSE) -> Phang | F5: =VLOOKUP(B5,All!$B$4:$S$8977,5,FALSE) -> Huy | G5: =VLOOKUP(B5,All!$B$4:$S$8977,6,FALSE) -> M | H5: =VLOOKUP(B5,All!$B$4:$S$8977,7,FALSE) -> 35160 | I5: =VLOOKUP(B5,All!$B$4:$S$8977,8,FALSE) -> 43573 | J5: =VLOOKUP(B5,All!$B$4:$S$8977,9,FALSE) -> Production | K5: =VLOOKUP(B5,All!$B$4:$S$8977,10,FALSE) -> Warehouse Fabric | L5: =VLOOKUP(B5,All!$B$4:$S$8977,11,FALSE) -> Loader | M5: =VLOOKUP(B5,All!$B$4:$S$8977,12,FALSE) -> 192 | N5: =VLOOKUP(B5,All!$B$4:$S$8977,13,FALSE) -> 3 | O5: =VLOOKUP(B5,All!$B$4:$S$8977,14,FALSE) -> 0 | P5: =VLOOKUP(B5,All!$B$4:$S$8977,15,FALSE) -> 20 | Q5: =VLOOKUP(B5,All!$B$4:$S$8977,16,FALSE) -> 0 | R5: 7 | S5: 10 | T5: =SUM(M5:S5) -> 232 | Z5: =M5+AH5 -> 194 | AA5: =N5 -> 3 | AB5: =O5 -> 0 | AC5: =P5 -> 20 | AD5: =Q5 -> 0 | AE5: =R5 -> 7 | AF5: =S5 -> 10 | AG5: =SUM(Z5:AF5) -> 234 | AH5: 2 | AI5: 0 | AJ5: 0 | AK5: 0 | AL5: 0 | AM5: 0 | AN5: 0 | AO5: 2
A6: =1+A5 -> 3 | B6: 2966 | C6: =VLOOKUP(B6,All!$B$4:$S$8977,2,FALSE) -> ស្រី | D6: =VLOOKUP(B6,All!$B$4:$S$89977,3,FALSE) -> ភារុណ | E6: =VLOOKUP(B6,All!$B$4:$S$8977,4,FALSE) -> Srey | F6: =VLOOKUP(B6,All!$B$4:$S$8977,5,FALSE) -> Phearun | G6: =VLOOKUP(B6,All!$B$4:$S$8977,6,FALSE) -> M | H6: =VLOOKUP(B6,All!$B$4:$S$8977,7,FALSE) -> 28194 | I6: =VLOOKUP(B6,All!$B$4:$S$8977,8,FALSE) -> 43636 | J6: =VLOOKUP(B6,All!$B$4:$S$8977,9,FALSE) -> Production | K6: =VLOOKUP(B6,All!$B$4:$S$8977,10,FALSE) -> Warehouse Fabric | L6: =VLOOKUP(B6,All!$B$4:$S$8977,11,FALSE) -> Loader | M6: =VLOOKUP(B6,All!$B$4:$S$8977,12,FALSE) -> 192 | N6: =VLOOKUP(B6,All!$B$4:$S$8977,13,FALSE) -> 3 | O6: =VLOOKUP(B6,All!$B$4:$S$8977,14,FALSE) -> 0 | P6: =VLOOKUP(B6,All!$B$4:$S$8977,15,FALSE) -> 0 | Q6: =VLOOKUP(B6,All!$B$4:$S$8977,16,FALSE) -> 0 | R6: 7 | S6: 10 | T6: =SUM(M6:S6) -> 212 | Z6: =M6+AH6 -> 194 | AA6: =N6 -> 3 | AB6: =O6 -> 0 | AC6: =P6 -> 0 | AD6: =Q6 -> 0 | AE6: =R6 -> 7 | AF6: =S6 -> 10 | AG6: =SUM(Z6:AF6) -> 214 | AH6: 2 | AI6: 0 | AJ6: 0 | AK6: 0 | AL6: 0 | AM6: 0 | AN6: 0 | AO6: 2
A7: =1+A6 -> 4 | B7: 3095 | C7: =VLOOKUP(B7,All!$B$4:$S$8977,2,FALSE) -> វន្ត័ | D7: =VLOOKUP(B7,All!$B$4:$S$89977,3,FALSE) -> វណ្ណា | E7: =VLOOKUP(B7,All!$B$4:$S$8977,4,FALSE) -> Vourn | F7: =VLOOKUP(B7,All!$B$4:$S$8977,5,FALSE) -> Vanna | G7: =VLOOKUP(B7,All!$B$4:$S$8977,6,FALSE) -> M | H7: =VLOOKUP(B7,All!$B$4:$S$8977,7,FALSE) -> 33118 | I7: =VLOOKUP(B7,All!$B$4:$S$8977,8,FALSE) -> 43740 | J7: =VLOOKUP(B7,All!$B$4:$S$8977,9,FALSE) -> Production | K7: =VLOOKUP(B7,All!$B$4:$S$8977,10,FALSE) -> Warehouse Fabric | L7: =VLOOKUP(B7,All!$B$4:$S$8977,11,FALSE) -> Loader | M7: =VLOOKUP(B7,All!$B$4:$S$8977,12,FALSE) -> 192 | N7: =VLOOKUP(B7,All!$B$4:$S$8977,13,FALSE) -> 3 | O7: =VLOOKUP(B7,All!$B$4:$S$8977,14,FALSE) -> 0 | P7: =VLOOKUP(B7,All!$B$4:$S$8977,15,FALSE) -> 0 | Q7: =VLOOKUP(B7,All!$B$4:$S$8977,16,FALSE) -> 0 | R7: 7 | S7: 10 | T7: =SUM(M7:S7) -> 212 | Z7: =M7+AH7 -> 194 | AA7: =N7 -> 3 | AB7: =O7 -> 0 | AC7: =P7 -> 0 | AD7: =Q7 -> 0 | AE7: =R7 -> 7 | AF7: =S7 -> 10 | AG7: =SUM(Z7:AF7) -> 214 | AH7: 2 | AI7: 0 | AJ7: 0 | AK7: 0 | AL7: 0 | AM7: 0 | AN7: 0 | AO7: 2
A8: =1+A7 -> 5 | B8: 3205 | C8: =VLOOKUP(B8,All!$B$4:$S$8977,2,FALSE) -> សាន | D8: =VLOOKUP(B8,All!$B$4:$S$89977,3,FALSE) -> វាសនា | E8: =VLOOKUP(B8,All!$B$4:$S$8977,4,FALSE) -> SAN | F8: =VLOOKUP(B8,All!$B$4:$S$8977,5,FALSE) -> VEASNA | G8: =VLOOKUP(B8,All!$B$4:$S$8977,6,FALSE) -> M | H8: =VLOOKUP(B8,All!$B$4:$S$8977,7,FALSE) -> 33340 | I8: =VLOOKUP(B8,All!$B$4:$S$8977,8,FALSE) -> 43740 | J8: =VLOOKUP(B8,All!$B$4:$S$8977,9,FALSE) -> Production | K8: =VLOOKUP(B8,All!$B$4:$S$8977,10,FALSE) -> Warehouse Fabric | L8: =VLOOKUP(B8,All!$B$4:$S$8977,11,FALSE) -> Loader | M8: =VLOOKUP(B8,All!$B$4:$S$8977,12,FALSE) -> 192 | N8: =VLOOKUP(B8,All!$B$4:$S$8977,13,FALSE) -> 3 | O8: =VLOOKUP(B8,All!$B$4:$S$8977,14,FALSE) -> 0 | P8: =VLOOKUP(B8,All!$B$4:$S$8977,15,FALSE) -> 0 | Q8: =VLOOKUP(B8,All!$B$4:$S$8977,16,FALSE) -> 0 | R8: 7 | S8: 10 | T8: =SUM(M8:S8) -> 212 | Z8: =M8+AH8 -> 194 | AA8: =N8 -> 3 | AB8: =O8 -> 0 | AC8: =P8 -> 0 | AD8: =Q8 -> 0 | AE8: =R8 -> 7 | AF8: =S8 -> 10 | AG8: =SUM(Z8:AF8) -> 214 | AH8: 2 | AI8: 0 | AJ8: 0 | AK8: 0 | AL8: 0 | AM8: 0 | AN8: 0 | AO8: 2
A9: =1+A8 -> 6 | B9: 3542 | C9: =VLOOKUP(B9,All!$B$4:$S$8977,2,FALSE) -> ស៊ុន | D9: =VLOOKUP(B9,All!$B$4:$S$89977,3,FALSE) -> ប៊ុនធឿន | E9: =VLOOKUP(B9,All!$B$4:$S$8977,4,FALSE) -> SUN | F9: =VLOOKUP(B9,All!$B$4:$S$8977,5,FALSE) -> BUNTHOEUN | G9: =VLOOKUP(B9,All!$B$4:$S$8977,6,FALSE) -> M | H9: =VLOOKUP(B9,All!$B$4:$S$8977,7,FALSE) -> 34175 | I9: =VLOOKUP(B9,All!$B$4:$S$8977,8,FALSE) -> 43747 | J9: =VLOOKUP(B9,All!$B$4:$S$8977,9,FALSE) -> Production | K9: =VLOOKUP(B9,All!$B$4:$S$8977,10,FALSE) -> Warehouse Fabric | L9: =VLOOKUP(B9,All!$B$4:$S$8977,11,FALSE) -> Loader | M9: =VLOOKUP(B9,All!$B$4:$S$8977,12,FALSE) -> 192 | N9: =VLOOKUP(B9,All!$B$4:$S$8977,13,FALSE) -> 3 | O9: =VLOOKUP(B9,All!$B$4:$S$8977,14,FALSE) -> 0 | P9: =VLOOKUP(B9,All!$B$4:$S$8977,15,FALSE) -> 0 | Q9: =VLOOKUP(B9,All!$B$4:$S$8977,16,FALSE) -> 0 | R9: 7 | S9: 10 | T9: =SUM(M9:S9) -> 212 | Z9: =M9+AH9 -> 194 | AA9: =N9 -> 3 | AB9: =O9 -> 0 | AC9: =P9 -> 0 | AD9: =Q9 -> 0 | AE9: =R9 -> 7 | AF9: =S9 -> 10 | AG9: =SUM(Z9:AF9) -> 214 | AH9: 2 | AI9: 0 | AJ9: 0 | AK9: 0 | AL9: 0 | AM9: 0 | AN9: 0 | AO9: 2
A10: =1+A9 -> 7 | B10: 3647 | C10: =VLOOKUP(B10,All!$B$4:$S$8977,2,FALSE) -> សូ | D10: =VLOOKUP(B10,All!$B$4:$S$89977,3,FALSE) -> សារ៉ាន់ | E10: =VLOOKUP(B10,All!$B$4:$S$8977,4,FALSE) -> SO | F10: =VLOOKUP(B10,All!$B$4:$S$8977,5,FALSE) -> SARANN | G10: =VLOOKUP(B10,All!$B$4:$S$8977,6,FALSE) -> M | H10: =VLOOKUP(B10,All!$B$4:$S$8977,7,FALSE) -> 32782 | I10: =VLOOKUP(B10,All!$B$4:$S$8977,8,FALSE) -> 43754 | J10: =VLOOKUP(B10,All!$B$4:$S$8977,9,FALSE) -> Production | K10: =VLOOKUP(B10,All!$B$4:$S$8977,10,FALSE) -> Warehouse Fabric | L10: =VLOOKUP(B10,All!$B$4:$S$8977,11,FALSE) -> Loader | M10: =VLOOKUP(B10,All!$B$4:$S$8977,12,FALSE) -> 192 | N10: =VLOOKUP(B10,All!$B$4:$S$8977,13,FALSE) -> 3 | O10: =VLOOKUP(B10,All!$B$4:$S$8977,14,FALSE) -> 0 | P10: =VLOOKUP(B10,All!$B$4:$S$8977,15,FALSE) -> 20 | Q10: =VLOOKUP(B10,All!$B$4:$S$8977,16,FALSE) -> 0 | R10: 7 | S10: 10 | T10: =SUM(M10:S10) -> 232 | Z10: =M10+AH10 -> 194 | AA10: =N10 -> 3 | AB10: =O10 -> 0 | AC10: =P10 -> 20 | AD10: =Q10 -> 0 | AE10: =R10 -> 7 | AF10: =S10 -> 10 | AG10: =SUM(Z10:AF10) -> 234 | AH10: 2 | AI10: 0 | AJ10: 0 | AK10: 0 | AL10: 0 | AM10: 0 | AN10: 0 | AO10: 2
A11: =1+A10 -> 8 | B11: 4126 | C11: =VLOOKUP(B11,All!$B$4:$S$8977,2,FALSE) -> មឿន | D11: =VLOOKUP(B11,All!$B$4:$S$89977,3,FALSE) -> នូសុខវិច្ឆកា | E11: =VLOOKUP(B11,All!$B$4:$S$8977,4,FALSE) -> MOEUN | F11: =VLOOKUP(B11,All!$B$4:$S$8977,5,FALSE) -> NOU SOKVICHHIKA | G11: =VLOOKUP(B11,All!$B$4:$S$8977,6,FALSE) -> M | H11: =VLOOKUP(B11,All!$B$4:$S$8977,7,FALSE) -> 34278 | I11: =VLOOKUP(B11,All!$B$4:$S$8977,8,FALSE) -> 43810 | J11: =VLOOKUP(B11,All!$B$4:$S$8977,9,FALSE) -> Production | K11: =VLOOKUP(B11,All!$B$4:$S$8977,10,FALSE) -> Warehouse Fabric | L11: =VLOOKUP(B11,All!$B$4:$S$8977,11,FALSE) -> Loader | M11: =VLOOKUP(B11,All!$B$4:$S$8977,12,FALSE) -> 192 | N11: =VLOOKUP(B11,All!$B$4:$S$8977,13,FALSE) -> 3 | O11: =VLOOKUP(B11,All!$B$4:$S$8977,14,FALSE) -> 0 | P11: =VLOOKUP(B11,All!$B$4:$S$8977,15,FALSE) -> 0 | Q11: =VLOOKUP(B11,All!$B$4:$S$8977,16,FALSE) -> 0 | R11: 7 | S11: 10 | T11: =SUM(M11:S11) -> 212 | Z11: =M11+AH11 -> 194 | AA11: =N11 -> 3 | AB11: =O11 -> 0 | AC11: =P11 -> 0 | AD11: =Q11 -> 0 | AE11: =R11 -> 7 | AF11: =S11 -> 10 | AG11: =SUM(Z11:AF11) -> 214 | AH11: 2 | AI11: 0 | AJ11: 0 | AK11: 0 | AL11: 0 | AM11: 0 | AN11: 0 | AO11: 2
A12: =1+A11 -> 9 | B12: 4138 | C12: =VLOOKUP(B12,All!$B$4:$S$8977,2,FALSE) -> នេត | D12: =VLOOKUP(B12,All!$B$4:$S$89977,3,FALSE) -> ចាន់វ៉ាន់ឆៃ | E12: =VLOOKUP(B12,All!$B$4:$S$8977,4,FALSE) -> NET | F12: =VLOOKUP(B12,All!$B$4:$S$8977,5,FALSE) -> CHANVANCHHAY | G12: =VLOOKUP(B12,All!$B$4:$S$8977,6,FALSE) -> M | H12: =VLOOKUP(B12,All!$B$4:$S$8977,7,FALSE) -> 35345 | I12: =VLOOKUP(B12,All!$B$4:$S$8977,8,FALSE) -> 43822 | J12: =VLOOKUP(B12,All!$B$4:$S$8977,9,FALSE) -> Production | K12: =VLOOKUP(B12,All!$B$4:$S$8977,10,FALSE) -> Warehouse Fabric | L12: =VLOOKUP(B12,All!$B$4:$S$8977,11,FALSE) -> Loader | M12: =VLOOKUP(B12,All!$B$4:$S$8977,12,FALSE) -> 192 | N12: =VLOOKUP(B12,All!$B$4:$S$8977,13,FALSE) -> 3 | O12: =VLOOKUP(B12,All!$B$4:$S$8977,14,FALSE) -> 0 | P12: =VLOOKUP(B12,All!$B$4:$S$8977,15,FALSE) -> 0 | Q12: =VLOOKUP(B12,All!$B$4:$S$8977,16,FALSE) -> 0 | R12: 7 | S12: 10 | T12: =SUM(M12:S12) -> 212 | Z12: =M12+AH12 -> 194 | AA12: =N12 -> 3 | AB12: =O12 -> 0 | AC12: =P12 -> 0 | AD12: =Q12 -> 0 | AE12: =R12 -> 7 | AF12: =S12 -> 10 | AG12: =SUM(Z12:AF12) -> 214 | AH12: 2 | AI12: 0 | AJ12: 0 | AK12: 0 | AL12: 0 | AM12: 0 | AN12: 0 | AO12: 2
A13: =1+A12 -> 10 | B13: 5172 | C13: =VLOOKUP(B13,All!$B$4:$S$8977,2,FALSE) -> អឹម | D13: =VLOOKUP(B13,All!$B$4:$S$89977,3,FALSE) -> ថេ | E13: =VLOOKUP(B13,All!$B$4:$S$8977,4,FALSE) -> OEM | F13: =VLOOKUP(B13,All!$B$4:$S$8977,5,FALSE) -> THE | G13: =VLOOKUP(B13,All!$B$4:$S$8977,6,FALSE) -> M | H13: =VLOOKUP(B13,All!$B$4:$S$8977,7,FALSE) -> 35160 | I13: =VLOOKUP(B13,All!$B$4:$S$8977,8,FALSE) -> 44485 | J13: =VLOOKUP(B13,All!$B$4:$S$8977,9,FALSE) -> Production | K13: =VLOOKUP(B13,All!$B$4:$S$8977,10,FALSE) -> Warehouse Fabric | L13: =VLOOKUP(B13,All!$B$4:$S$8977,11,FALSE) -> Loader | M13: =VLOOKUP(B13,All!$B$4:$S$8977,12,FALSE) -> 187 | N13: =VLOOKUP(B13,All!$B$4:$S$8977,13,FALSE) -> 0 | O13: =VLOOKUP(B13,All!$B$4:$S$8977,14,FALSE) -> 0 | P13: =VLOOKUP(B13,All!$B$4:$S$8977,15,FALSE) -> 0 | Q13: =VLOOKUP(B13,All!$B$4:$S$8977,16,FALSE) -> 0 | R13: 7 | S13: 10 | T13: =SUM(M13:S13) -> 204 | Z13: =M13+AH13 -> 189 | AA13: =N13 -> 0 | AB13: =O13 -> 0 | AC13: =P13 -> 0 | AD13: =Q13 -> 0 | AE13: =R13 -> 7 | AF13: =S13 -> 10 | AG13: =SUM(Z13:AF13) -> 206 | AH13: 2 | AI13: 0 | AJ13: 0 | AK13: 0 | AL13: 0 | AM13: 0 | AN13: 0 | AO13: 2
A14: =1+A13 -> 11 | B14: 5173 | C14: =VLOOKUP(B14,All!$B$4:$S$8977,2,FALSE) -> ណុប | D14: =VLOOKUP(B14,All!$B$4:$S$89977,3,FALSE) -> គីនីន | E14: =VLOOKUP(B14,All!$B$4:$S$8977,4,FALSE) -> NOP | F14: =VLOOKUP(B14,All!$B$4:$S$8977,5,FALSE) -> KININ | G14: =VLOOKUP(B14,All!$B$4:$S$8977,6,FALSE) -> M | H14: =VLOOKUP(B14,All!$B$4:$S$8977,7,FALSE) -> 30729 | I14: =VLOOKUP(B14,All!$B$4:$S$8977,8,FALSE) -> 44485 | J14: =VLOOKUP(B14,All!$B$4:$S$8977,9,FALSE) -> Production | K14: =VLOOKUP(B14,All!$B$4:$S$8977,10,FALSE) -> Warehouse Fabric | L14: =VLOOKUP(B14,All!$B$4:$S$8977,11,FALSE) -> Loader | M14: =VLOOKUP(B14,All!$B$4:$S$8977,12,FALSE) -> 187 | N14: =VLOOKUP(B14,All!$B$4:$S$8977,13,FALSE) -> 0 | O14: =VLOOKUP(B14,All!$B$4:$S$8977,14,FALSE) -> 0 | P14: =VLOOKUP(B14,All!$B$4:$S$8977,15,FALSE) -> 0 | Q14: =VLOOKUP(B14,All!$B$4:$S$8977,16,FALSE) -> 0 | R14: 7 | S14: 10 | T14: =SUM(M14:S14) -> 204 | Z14: =M14+AH14 -> 189 | AA14: =N14 -> 0 | AB14: =O14 -> 0 | AC14: =P14 -> 0 | AD14: =Q14 -> 0 | AE14: =R14 -> 7 | AF14: =S14 -> 10 | AG14: =SUM(Z14:AF14) -> 206 | AH14: 2 | AI14: 0 | AJ14: 0 | AK14: 0 | AL14: 0 | AM14: 0 | AN14: 0 | AO14: 2
T16: =SUM(T4:T14) -> 2402 | AG16: =SUM(AG4:AG14) -> 2424 | AH16: =SUM(AH4:AH14) -> 22 | AI16: =SUM(AI4:AI14) -> 0

Sheet WH Trims
A1: ល.រ | B1: Factory ID | C1: គោត្តនាម | D1: នាម | E1: គោត្តនាមឡាតាំង | F1: នាមឡាតាំង | G1: ភេទ | H1: ថ្ងៃខែឆ្នាំកំណើត | I1: កាលបរិ. ចូលធ្វើការ | J1: ផ្នែក | K1: ក្រុម | L1: តួនាទី | M1: Salary Report 2021 | U1: Adjust amount | V1: Adjust Date | W1: Evaluator | X1: 2022 Total Marks | Y1: With Comment | Z1: Salary Report 2022
A2: Nº | B2: Factory ID | C2: Khmer Sure name | D2: Khmer Name | E2: English Sure name | F2: Khmer Name | G2: Sex | H2: Birth of Date | I2: Join Date | J2: Department | K2: Group | L2: Position | M2: Basic | N2: Seniority | O2: Skill | P2: Position | Q2: Language | R2: Housing &Transportation | S2: Motivation | T2: Total | U2: 調動金額 | V2: 調動日期 | W2: 評核人 | X2: 2022總分 | Y2: 意見 | Z2: Basic | AA2: Seniority | AB2: Skill | AC2: Position | AD2: Language | AE2: Housing &Transportation | AF2: Motivation | AG2: Total
A3: 排序 | B3: 工號 | E3: 姓名 | G3: 性別 | H3: 生日 | I3: 入職日期 | J3: 部門 | K3: 組別 | L3: 崗位名稱 | M3: 底薪 | N3: 工齡 | O3: 技能 | P3: 職位 | Q3: 語言 | R3: 房屋/交通 | S3: 全勤 | T3: 2021薪資總額 | U3: 調動金額 | V3: 調動日期 | W3: 評核人 | X3: 2022總分 | Y3: 意見 | Z3: 底薪 | AA3: 工齡 | AB3: 技能 | AC3: 職位 | AD3: 語言 | AE3: 房屋/交通 | AF3: 全勤 | AG3: 2022薪資總額
A4: =1 -> 1 | B4: 316 | C4: =VLOOKUP(B4,All!$B$4:$S$8977,2,FALSE) -> រិន | D4: =VLOOKUP(B4,All!$B$4:$S$89977,3,FALSE) -> ចាន់ថា | E4: =VLOOKUP(B4,All!$B$4:$S$8977,4,FALSE) -> RIN | F4: =VLOOKUP(B4,All!$B$4:$S$8977,5,FALSE) -> CHANTHA | G4: =VLOOKUP(B4,All!$B$4:$S$8977,6,FALSE) -> F | H4: =VLOOKUP(B4,All!$B$4:$S$8977,7,FALSE) -> 34981 | I4: =VLOOKUP(B4,All!$B$4:$S$8977,8,FALSE) -> 41755 | J4: =VLOOKUP(B4,All!$B$4:$S$8977,9,FALSE) -> Production | K4: =VLOOKUP(B4,All!$B$4:$S$8977,10,FALSE) -> Warehouse Trims | L4: =VLOOKUP(B4,All!$B$4:$S$8977,11,FALSE) -> accessory assistant | M4: =VLOOKUP(B4,All!$B$4:$S$8977,12,FALSE) -> 192 | N4: =VLOOKUP(B4,All!$B$4:$S$8977,13,FALSE) -> 8 | O4: =VLOOKUP(B4,All!$B$4:$S$8977,14,FALSE) -> 20 | P4: =VLOOKUP(B4,All!$B$4:$S$8977,15,FALSE) -> 20 | Q4: =VLOOKUP(B4,All!$B$4:$S$8977,16,FALSE) -> 0 | R4: 7 | S4: 10 | T4: =SUM(M4:S4) -> 257 | Z4: =M4+AH4 -> 194 | AA4: =N4 -> 8 | AB4: =O4 -> 20 | AC4: =P4 -> 20 | AD4: =Q4 -> 0 | AE4: =R4 -> 7 | AF4: =S4 -> 10 | AG4: =SUM(Z4:AF4) -> 259 | AH4: 2 | AI4: 0 | AJ4: 0 | AK4: 0 | AL4: 0 | AM4: 0 | AN4: 0 | AO4: 2
A5: =1+A4 -> 2 | B5: 2974 | C5: =VLOOKUP(B5,All!$B$4:$S$8977,2,FALSE) -> ស៊ុំ | D5: =VLOOKUP(B5,All!$B$4:$S$89977,3,FALSE) -> ហ៊ីង | E5: =VLOOKUP(B5,All!$B$4:$S$8977,4,FALSE) -> Sum | F5: =VLOOKUP(B5,All!$B$4:$S$8977,5,FALSE) -> Hing | G5: =VLOOKUP(B5,All!$B$4:$S$8977,6,FALSE) -> F | H5: =VLOOKUP(B5,All!$B$4:$S$8977,7,FALSE) -> 28470 | I5: =VLOOKUP(B5,All!$B$4:$S$8977,8,FALSE) -> 43636 | J5: =VLOOKUP(B5,All!$B$4:$S$8977,9,FALSE) -> Production | K5: =VLOOKUP(B5,All!$B$4:$S$8977,10,FALSE) -> Warehouse Trims | L5: =VLOOKUP(B5,All!$B$4:$S$8977,11,FALSE) -> accessory assistant | M5: =VLOOKUP(B5,All!$B$4:$S$8977,12,FALSE) -> 192 | N5: =VLOOKUP(B5,All!$B$4:$S$8977,13,FALSE) -> 3 | O5: =VLOOKUP(B5,All!$B$4:$S$8977,14,FALSE) -> 0 | P5: =VLOOKUP(B5,All!$B$4:$S$8977,15,FALSE) -> 0 | Q5: =VLOOKUP(B5,All!$B$4:$S$8977,16,FALSE) -> 0 | R5: 7 | S5: 10 | T5: =SUM(M5:S5) -> 212 | Z5: =M5+AH5 -> 194 | AA5: =N5 -> 3 | AB5: =O5 -> 0 | AC5: =P5 -> 0 | AD5: =Q5 -> 0 | AE5: =R5 -> 7 | AF5: =S5 -> 10 | AG5: =SUM(Z5:AF5) -> 214 | AH5: 2 | AI5: 0 | AJ5: 0 | AK5: 0 | AL5: 0 | AM5: 0 | AN5: 0 | AO5: 2
A6: =1+A5 -> 3 | B6: 3053 | C6: =VLOOKUP(B6,All!$B$4:$S$8977,2,FALSE) -> សន់ | D6: =VLOOKUP(B6,All!$B$4:$S$89977,3,FALSE) -> សុឧត្តម | E6: =VLOOKUP(B6,All!$B$4:$S$8977,4,FALSE) -> Sann | F6: =VLOOKUP(B6,All!$B$4:$S$8977,5,FALSE) -> Sodom | G6: =VLOOKUP(B6,All!$B$4:$S$8977,6,FALSE) -> M | H6: =VLOOKUP(B6,All!$B$4:$S$8977,7,FALSE) -> 36524 | I6: =VLOOKUP(B6,All!$B$4:$S$8977,8,FALSE) -> 43653 | J6: =VLOOKUP(B6,All!$B$4:$S$8977,9,FALSE) -> Production | K6: =VLOOKUP(B6,All!$B$4:$S$8977,10,FALSE) -> Warehouse Trims | L6: =VLOOKUP(B6,All!$B$4:$S$8977,11,FALSE) -> accessory assistant | M6: =VLOOKUP(B6,All!$B$4:$S$8977,12,FALSE) -> 192 | N6: =VLOOKUP(B6,All!$B$4:$S$8977,13,FALSE) -> 3 | O6: =VLOOKUP(B6,All!$B$4:$S$8977,14,FALSE) -> 0 | P6: =VLOOKUP(B6,All!$B$4:$S$8977,15,FALSE) -> 0 | Q6: =VLOOKUP(B6,All!$B$4:$S$8977,16,FALSE) -> 0 | R6: 7 | S6: 10 | T6: =SUM(M6:S6) -> 212 | Z6: =M6+AH6 -> 194 | AA6: =N6 -> 3 | AB6: =O6 -> 0 | AC6: =P6 -> 0 | AD6: =Q6 -> 0 | AE6: =R6 -> 7 | AF6: =S6 -> 10 | AG6: =SUM(Z6:AF6) -> 214 | AH6: 2 | AI6: 0 | AJ6: 0 | AK6: 0 | AL6: 0 | AM6: 0 | AN6: 0 | AO6: 2
A7: =1+A6 -> 4 | B7: 5002 | C7: =VLOOKUP(B7,All!$B$4:$S$8977,2,FALSE) -> អ៊ុក | D7: =VLOOKUP(B7,All!$B$4:$S$89977,3,FALSE) -> ស្រីណូ | E7: =VLOOKUP(B7,All!$B$4:$S$8977,4,FALSE) -> OUK | F7: =VLOOKUP(B7,All!$B$4:$S$8977,5,FALSE) -> SREYNO | G7: =VLOOKUP(B7,All!$B$4:$S$8977,6,FALSE) -> F | H7: =VLOOKUP(B7,All!$B$4:$S$8977,7,FALSE) -> 34713 | I7: =VLOOKUP(B7,All!$B$4:$S$8977,8,FALSE) -> 44139 | J7: =VLOOKUP(B7,All!$B$4:$S$8977,9,FALSE) -> Production | K7: =VLOOKUP(B7,All!$B$4:$S$8977,10,FALSE) -> Warehouse Trims | L7: =VLOOKUP(B7,All!$B$4:$S$8977,11,FALSE) -> accessory assistant | M7: =VLOOKUP(B7,All!$B$4:$S$8977,12,FALSE) -> 192 | N7: =VLOOKUP(B7,All!$B$4:$S$8977,13,FALSE) -> 2 | O7: =VLOOKUP(B7,All!$B$4:$S$8977,14,FALSE) -> 0 | P7: =VLOOKUP(B7,All!$B$4:$S$8977,15,FALSE) -> 0 | Q7: =VLOOKUP(B7,All!$B$4:$S$8977,16,FALSE) -> 0 | R7: 7 | S7: 10 | T7: =SUM(M7:S7) -> 211 | Z7: =M7+AH7 -> 194 | AA7: =N7 -> 2 | AB7: =O7 -> 0 | AC7: =P7 -> 0 | AD7: =Q7 -> 0 | AE7: =R7 -> 7 | AF7: =S7 -> 10 | AG7: =SUM(Z7:AF7) -> 213 | AH7: 2 | AI7: 0 | AJ7: 0 | AK7: 0 | AL7: 0 | AM7: 0 | AN7: 0 | AO7: 2
A8: =1+A7 -> 5 | B8: 5093 | C8: =VLOOKUP(B8,All!$B$4:$S$8977,2,FALSE) -> ស៊ិន​ | D8: =VLOOKUP(B8,All!$B$4:$S$89977,3,FALSE) -> សាវ៉ើន | E8: =VLOOKUP(B8,All!$B$4:$S$8977,4,FALSE) -> SIN | F8: =VLOOKUP(B8,All!$B$4:$S$8977,5,FALSE) -> SAVOEUN | G8: =VLOOKUP(B8,All!$B$4:$S$8977,6,FALSE) -> M | H8: =VLOOKUP(B8,All!$B$4:$S$8977,7,FALSE) -> 35524 | I8: =VLOOKUP(B8,All!$B$4:$S$8977,8,FALSE) -> 44421 | J8: =VLOOKUP(B8,All!$B$4:$S$8977,9,FALSE) -> Production | K8: =VLOOKUP(B8,All!$B$4:$S$8977,10,FALSE) -> Warehouse Trims | L8: =VLOOKUP(B8,All!$B$4:$S$8977,11,FALSE) -> accessory assistant | M8: =VLOOKUP(B8,All!$B$4:$S$8977,12,FALSE) -> 187 | N8: =VLOOKUP(B8,All!$B$4:$S$8977,13,FALSE) -> 0 | O8: =VLOOKUP(B8,All!$B$4:$S$8977,14,FALSE) -> 0 | P8: =VLOOKUP(B8,All!$B$4:$S$8977,15,FALSE) -> 0 | Q8: =VLOOKUP(B8,All!$B$4:$S$8977,16,FALSE) -> 0 | R8: 7 | S8: 10 | T8: =SUM(M8:S8) -> 204 | Z8: =M8+AH8 -> 189 | AA8: =N8 -> 0 | AB8: =O8 -> 0 | AC8: =P8 -> 0 | AD8: =Q8 -> 0 | AE8: =R8 -> 7 | AF8: =S8 -> 10 | AG8: =SUM(Z8:AF8) -> 206 | AH8: 2 | AI8: 0 | AJ8: 0 | AK8: 0 | AL8: 0 | AM8: 0 | AN8: 0 | AO8: 2
A9: =1+A8 -> 6 | B9: 5088 | C9: =VLOOKUP(B9,All!$B$4:$S$8977,2,FALSE) -> ម៉ុស | D9: =VLOOKUP(B9,All!$B$4:$S$89977,3,FALSE) -> ប៊ុនធី | E9: =VLOOKUP(B9,All!$B$4:$S$8977,4,FALSE) -> MOS | F9: =VLOOKUP(B9,All!$B$4:$S$8977,5,FALSE) -> BUNTHY | G9: =VLOOKUP(B9,All!$B$4:$S$8977,6,FALSE) -> M | H9: =VLOOKUP(B9,All!$B$4:$S$8977,7,FALSE) -> 33060 | I9: =VLOOKUP(B9,All!$B$4:$S$8977,8,FALSE) -> 44399 | J9: =VLOOKUP(B9,All!$B$4:$S$8977,9,FALSE) -> Production | K9: =VLOOKUP(B9,All!$B$4:$S$8977,10,FALSE) -> Warehouse Trims | L9: =VLOOKUP(B9,All!$B$4:$S$8977,11,FALSE) -> accessory assistant | M9: =VLOOKUP(B9,All!$B$4:$S$8977,12,FALSE) -> 192 | N9: =VLOOKUP(B9,All!$B$4:$S$8977,13,FALSE) -> 0 | O9: =VLOOKUP(B9,All!$B$4:$S$8977,14,FALSE) -> 0 | P9: =VLOOKUP(B9,All!$B$4:$S$8977,15,FALSE) -> 0 | Q9: =VLOOKUP(B9,All!$B$4:$S$8977,16,FALSE) -> 0 | R9: 7 | S9: 10 | T9: =SUM(M9:S9) -> 209 | Z9: =M9+AH9 -> 194 | AA9: =N9 -> 0 | AB9: =O9 -> 0 | AC9: =P9 -> 0 | AD9: =Q9 -> 0 | AE9: =R9 -> 7 | AF9: =S9 -> 10 | AG9: =SUM(Z9:AF9) -> 211 | AH9: 2 | AI9: 0 | AJ9: 0 | AK9: 0 | AL9: 0 | AM9: 0 | AN9: 0 | AO9: 2
A10: =1+A9 -> 7 | B10: 5089 | C10: =VLOOKUP(B10,All!$B$4:$S$8977,2,FALSE) -> បេន | D10: =VLOOKUP(B10,All!$B$4:$S$89977,3,FALSE) -> ខេមរ៉ា | E10: =VLOOKUP(B10,All!$B$4:$S$8977,4,FALSE) -> BEN | F10: =VLOOKUP(B10,All!$B$4:$S$8977,5,FALSE) -> KHEMRA | G10: =VLOOKUP(B10,All!$B$4:$S$8977,6,FALSE) -> F | H10: =VLOOKUP(B10,All!$B$4:$S$8977,7,FALSE) -> 32234 | I10: =VLOOKUP(B10,All!$B$4:$S$8977,8,FALSE) -> 44400 | J10: =VLOOKUP(B10,All!$B$4:$S$8977,9,FALSE) -> Production | K10: =VLOOKUP(B10,All!$B$4:$S$8977,10,FALSE) -> Warehouse Trims | L10: =VLOOKUP(B10,All!$B$4:$S$8977,11,FALSE) -> accessory assistant | M10: =VLOOKUP(B10,All!$B$4:$S$8977,12,FALSE) -> 192 | N10: =VLOOKUP(B10,All!$B$4:$S$8977,13,FALSE) -> 0 | O10: =VLOOKUP(B10,All!$B$4:$S$8977,14,FALSE) -> 0 | P10: =VLOOKUP(B10,All!$B$4:$S$8977,15,FALSE) -> 0 | Q10: =VLOOKUP(B10,All!$B$4:$S$8977,16,FALSE) -> 0 | R10: 7 | S10: 10 | T10: =SUM(M10:S10) -> 209 | Z10: =M10+AH10 -> 194 | AA10: =N10 -> 0 | AB10: =O10 -> 0 | AC10: =P10 -> 0 | AD10: =Q10 -> 0 | AE10: =R10 -> 7 | AF10: =S10 -> 10 | AG10: =SUM(Z10:AF10) -> 211 | AH10: 2 | AI10: 0 | AJ10: 0 | AK10: 0 | AL10: 0 | AM10: 0 | AN10: 0 | AO10: 2
